Workbook

Sheet 미입금(휴먼)
D1: 합계금액 | E1: 공급가액 | F1: 세액
C2: 합계 | D2: =SUM(D5:D1126) -> 27002375 | E2: =SUM(E5:E1126) -> 25000770 | F2: =SUM(F5:F1126) -> 2001605
B3: 업체 미입금내역(휴먼)
B4: 작성일자 | C4: 상호 | D4: 합계금액 | E4: 공급가액 | F4: 세액 | G4: 품목비고
A5: =ROW(A5)-4 -> 1 | B5: 46096 | C5: (주)삼구아이앤씨 | D5: 16467275 | E5: 14970250 | F5: 1497025 | G5: 일용비 (소노벨-룸메이드)
A6: =ROW(A6)-4 -> 2 | B6: 46096 | C6: (주)삼구아이앤씨 | D6: 5550380 | E6: 5045800 | F6: 504580 | G6: 일용비 (소노캄-룸메이드)
A7: =ROW(A7)-4 -> 3 | B7: 46101 | C7: 완도군내LH1단지아파트관리사무소 | D7: 4984720 | E7: 4984720 | F7: 0 | G7: 03월 경비용역비

Sheet 매출(휴먼)
A1: 주식회사 휴먼엠에스 | I1: 공급가액합계 | J1: =SUM(D4:D314) -> 978891830 | K1: =SUM(D315:D885) -> 2238896840 | L1: =SUM(D886:D1358) -> 2400598440 | M1: =SUM(D1359:D1684) -> 2412642418 | N1: =SUM(D1685:D2109) -> 3186033695 | O1: =SUM(D2110:D2732) -> 4952107244 | P1: =SUM(D2733:D3375) -> 4127550188 | Q1: =SUM(D3376:D3961) -> 5324478103 | R1: =SUM(D3962:D4237) -> 3563807712 | S1: =SUM(D4238:D4441) -> 645778498
I2: 세액합계 | J2: =SUM(E4:E314) -> 97889176 | K2: =SUM(E315:E885) -> 223889682 | L2: =SUM(E886:E1358) -> 240059844 | M2: =SUM(E1359:E1684) -> 241264240 | N2: =SUM(E1685:E2109) -> 318603368 | O2: =SUM(E2110:E2732) -> 495210738 | P2: =SUM(E2733:E3375) -> 4.0184248e+08 | Q2: =SUM(E3376:E3961) -> 493523666 | R2: =SUM(E3962:E4237) -> 338738423 | S2: =SUM(E4238:E4441) -> 63082955
A3: 작성일자 | B3: 상호 | C3: 합계금액 | D3: 공급가액 | E3: 세액 | F3: 비고 | G3: 입금일 | J3: 2017년 | K3: 2018년 | L3: 2019년 | M3: 2020년 | N3: 2021년 | O3: 2022년 | P3: 2023년 | Q3: 2024년 | R3: 2025년 | S3: 2026년
A4: 2017-04-10 | B4: 미성엠프로 주식회사 | C4: -18271000 | D4: -16610000 | E4: -1661000 | F4: 시흥(4/2~4/6) | G4: 취소전표
A5: 2017-04-10 | B5: 미성엠프로 주식회사 | C5: -17611000 | D5: -16010000 | E5: -1601000 | F5: (시흥-4/7~4/8) | G5: 취소전표
A6: 2017-04-10 | B6: 미성엠프로 주식회사 | C6: 17611000 | D6: 16010000 | E6: 1601000 | F6: (시흥-4/7~4/8) | G6: 취소전표
A7: 2017-04-10 | B7: 미성엠프로 주식회사 | C7: 18271000 | D7: 16610000 | E7: 1661000 | F7: 시흥(4/2~4/6) | G7: 취소전표
A8: 2017-04-05 | B8: 미성엠프로 주식회사 | C8: =SUM(D8:E8) -> 8767000 | D8: 7970000 | E8: 797000 | G8: 42831
A9: 2017-04-10 | B9: 미성엠프로 주식회사 | C9: =SUM(D9:E9) -> 17127000 | D9: 15570000 | E9: 1557000 | F9: (시흥-4/7~4/8) | G9: 42836
A10: 2017-04-10 | B10: 미성엠프로 주식회사 | C10: =SUM(D10:E10) -> 17853000 | D10: 16230000 | E10: 1623000 | F10: (시흥-4/2~4/6) | G10: 42836
A11: 2017-04-12 | B11: 미성엠프로 주식회사 | C11: =SUM(D11:E11) -> 10351000 | D11: 9410000 | E11: 941000 | F11: 시흥(4/09~4/10) | G11: 42839
A12: 2017-04-17 | B12: 미성엠프로 주식회사 | C12: =SUM(D12:E12) -> 7623000 | D12: 6930000 | E12: 693000 | F12: (시흥-4/11~4/12) | G12: 42842
A13: 2017-04-17 | B13: 미성엠프로 주식회사 | C13: =SUM(D13:E13) -> 6336000 | D13: 5760000 | E13: 576000 | F13: (시흥-4/13~4/14) | G13: 42842
A14: 2017-04-18 | B14: 미성엠프로 주식회사 | C14: =SUM(D14:E14) -> 18018000 | D14: 16380000 | E14: 1638000 | F14: (시흥-4/15~4/16) | G14: 42844
A15: 2017-04-20 | B15: 가오프로젝트(G.A.O PROJECT) | C15: =SUM(D15:E15) -> 32599600 | D15: 29636000 | E15: 2963600 | G15: 42845
A16: 2017-04-21 | B16: 주식회사 프레임컴퍼니 | C16: =SUM(D16:E16) -> 6105000 | D16: 5550000 | E16: 555000 | G16: 42853
A17: 2017-04-24 | B17: 미성엠프로 주식회사 | C17: =SUM(D17:E17) -> 15356000 | D17: 13960000 | E17: 1396000 | F17: (시흥-4/22~4/23) | G17: 42853
A18: 2017-04-24 | B18: 미성엠프로 주식회사 | C18: =SUM(D18:E18) -> 3960000 | D18: 3600000 | E18: 360000 | F18: (시흥-4/17~4/21) | G18: 42867
A19: 2017-04-30 | B19: (주)씨엔에스자산관리 | C19: =SUM(D19:E19) -> 16500000 | D19: 15000000 | E19: 1500000 | G19: 42874 | I19: 4월
A20: 2017-04-30 | B20: 미성엠프로 주식회사 | C20: =SUM(D20:E20) -> 3960000 | D20: 3600000 | E20: 360000 | F20: (시흥-4/24~4/28) | G20: 42853 | I20: 합계 | J20: 공급 | K20: 세액
A21: 2017-04-30 | B21: 미성엠프로 주식회사 | C21: =SUM(D21:E21) -> 12188000 | D21: 11080000 | E21: 1108000 | F21: (시흥-4/29~4/30) | G21: 42867 | I21: =SUM(C4:C21) -> 176743600 | J21: =SUM(D4:D21) -> 160676000 | K21: =SUM(E4:E21) -> 16067600
A22: 2017-05-04 | B22: 미성엠프로 주식회사 | C22: -6336000 | D22: -5760000 | E22: -576000 | F22: (시흥-5/1~5/2) | G22: 취소전표
A23: 2017-05-04 | B23: 미성엠프로 주식회사 | C23: 6336000 | D23: 5760000 | E23: 576000 | F23: (시흥-5/1~5/2) | G23: 취소전표
A24: 2017-05-04 | B24: 미성엠프로 주식회사 | C24: =SUM(D24:E24) -> 6556000 | D24: 5960000 | E24: 596000 | F24: (시흥 5/01~5/02) | G24: 42866
A25: 2017-05-08 | B25: 미성엠프로 주식회사 | C25: =SUM(D25:E25) -> 28468000 | D25: 25880000 | E25: 2588000 | F25: (시흥-5/03~5/07) | G25: 42866
A26: 2017-05-10 | B26: (주)씨엔에스자산관리 | C26: =SUM(D26:E26) -> 31240000 | D26: 28400000 | E26: 2840000 | F26: (송도 5/01~5/09) | G26: 42881
A27: 2017-05-10 | B27: 미성엠프로 주식회사 | C27: =SUM(D27:E27) -> 9460000 | D27: 8600000 | E27: 860000 | F27: (시흥 5/08~5/09) | G27: 42867
A28: 2017-05-17 | B28: 미성엠프로 주식회사 | C28: =SUM(D28:E28) -> 12540000 | D28: 11400000 | E28: 1140000 | F28: (시흥-5/13~5/14) | G28: 42877
A29: 2017-05-17 | B29: 미성엠프로 주식회사 | C29: =SUM(D29:E29) -> 2640000 | D29: 2400000 | E29: 240000 | F29: (시흥-5/10~5/12) | G29: 42877
A30: 2017-05-24 | B30: 미성엠프로 주식회사 | C30: =SUM(D30:E30) -> 11396000 | D30: 10360000 | E30: 1036000 | F30: (시흥-5/20~5/21) | G30: 42895 | I30: 5월
A31: 2017-05-25 | B31: (주)씨엔에스자산관리 | C31: =SUM(D31:E31) -> 12573000 | D31: 11430000 | E31: 1143000 | F31: (송도-5/10~5/21) | G31: 42898 | I31: 합계 | J31: 공급 | K31: 세액
A32: 42886 | B32: 미성엠프로 주식회사 | C32: 11264000 | D32: 10240000 | E32: 1024000 | F32: (시흥-5/27~5/28) | G32: 42895 | I32: =SUM(C22:C32) -> 126137000 | J32: =SUM(D22:D32) -> 114670000 | K32: =SUM(E22:E32) -> 11467000
A33: 2017-06-04 | B33: 미성엠프로 주식회사 | C33: 11665500 | D33: 10605000 | E33: 1060500 | F33: (시흥-6/03~6/04) | G33: 42916
A34: 2017-06-04 | B34: 미성엠프로 주식회사 | C34: 11671000 | D34: 10610000 | E34: 1061000 | F34: (시흥-6/03~6/04) | G34: 취소전표
A35: 2017-06-09 | B35: (주)씨엔에스자산관리 | C35: -3168000 | D35: -2880000 | E35: -288000 | F35: 인천-5/27~6/04 | G35: 취소전표
A36: 2017-06-09 | B36: (주)씨엔에스자산관리 | C36: 3168000 | D36: 2880000 | E36: 288000 | F36: 인천-5/27~6/04 | G36: 취소전표 | I36: 6월
A37: 2017-06-26 | B37: 미성엠프로 주식회사 | C37: -11671000 | D37: -10610000 | E37: -1061000 | F37: (시흥-6/03~6/04) | G37: 취소전표 | I37: 합계 | J37: 공급 | K37: 세액
A38: 2017-06-30 | B38: 미성엠프로 주식회사 | C38: 12320000 | D38: 11200000 | E38: 1120000 | F38: 일용비(삼성서울병원) | G38: 42927 | I38: =SUM(C33:C38) -> 23985500 | J38: =SUM(D33:D38) -> 21805000 | K38: =SUM(E33:E38) -> 2180500
A39: 2017-07-01 | B39: (주)씨엔에스자산관리 | C39: 3168000 | D39: 2880000 | E39: 288000 | F39: 인천-5/27~6/04 | G39: 취소전표(7/1)
A40: 2017-07-12 | B40: (주)씨엔에스자산관리 | C40: 4752000 | D40: 4320000 | E40: 432000 | F40: (6/10~7/02) | G40: 42942
...

Sheet 매입계산서(휴먼)
C1: 합계금액 | D1: 공급가액 | E1: 세액
B2: 휴먼합계 | C2: =SUM(C6:C10036) -> 6613794228 | D2: =SUM(D6:D10036) -> 6013318316 | E2: =SUM(E6:E10036) -> 600475912
A3: 매입계산서
A4: 주식회사 휴먼엠에스
A5: 작성일자 | B5: 상호 | C5: 합계금액 | D5: 공급가액 | E5: 세액 | F5: 품목비고
A6: 2017-03-15 | B6: (주)아마존카 | C6: 251200 | D6: 228364 | E6: 22836 | F6: 승계수수료
A7: 2017-03-27 | B7: (주)아마존카 | C7: -79317 | D7: -72107 | E7: -7210 | F7: 37회차 대여료
A8: 2017-03-27 | B8: (주)아마존카 | C8: 295650 | D8: 268773 | E8: 26877 | F8: 37회차 대여료
A9: 2017-04-06 | B9: 초월피복 | C9: 1064800 | D9: 968000 | E9: 96800 | F9: 안전모 안전조끼
A10: 2017-04-10 | B10: 초월피복 | C10: 193600 | D10: 176000 | E10: 17600 | F10: 안전모
A11: 2017-04-10 | B11: 초월피복 | C11: 985600 | D11: 896000 | E11: 89600 | F11: 안전모
A12: 2017-04-10 | B12: 초월피복 | C12: -1064800 | D12: -968000 | E12: -96800 | F12: 안전모 안전조끼
A13: 2017-04-10 | B13: （주）아웃소싱화인 | C13: 11880000 | D13: 10800000 | E13: 1080000 | F13: 외주용역비
A14: 2017-04-11 | B14: （주）아웃소싱화인 | C14: 825000 | D14: 750000 | E14: 75000 | F14: 외주용역비
A15: 2017-04-15 | B15: (주)아마존카 | C15: 282847 | D15: 257134 | E15: 25713 | F15: 38회차 대여료
A16: 2017-04-24 | B16: (주) 어배인 | C16: 7832000 | D16: 7120000 | E16: 712000
A17: 2017-05-15 | B17: (주)아마존카 | C17: 446600 | D17: 406000 | E17: 40600 | F17: 39회차 대여료
A18: 2017-06-15 | B18: (주)아마존카 | C18: 446600 | D18: 406000 | E18: 40600 | F18: 40회차 대여료
A19: 2017-06-30 | B19: 법무법인 정론 서초분사무소 | C19: 111000 | D19: 100910 | E19: 10090 | F19: 수수료
A20: 2017-07-15 | B20: (주)아마존카 | C20: 446600 | D20: 406000 | E20: 40600 | F20: 41회차 대여료
A21: 2017-08-15 | B21: (주)아마존카 | C21: 446600 | D21: 406000 | E21: 40600 | F21: 42회차 대여료
A22: 2017-09-15 | B22: (주)아마존카 | C22: 446600 | D22: 406000 | E22: 40600 | F22: 43회차 대여료
A23: 2017-09-28 | B23: 잡코리아 유한책임회사 | C23: 12100 | D23: 11000 | E23: 1100 | F23: 알바몬 유료 서비스
A24: 2017-09-29 | B24: 잡코리아 유한책임회사 | C24: 162400 | D24: 147636 | E24: 14764 | F24: 알바몬 유료 서비스
A25: 2017-10-15 | B25: (주)아마존카 | C25: 446600 | D25: 406000 | E25: 40600 | F25: 44회차 대여료
A26: 2017-10-17 | B26: 잡코리아 유한책임회사 | C26: 338000 | D26: 307273 | E26: 30727 | F26: 알바몬 유료 서비스
A27: 2017-10-18 | B27: 잡코리아 유한책임회사 | C27: 162400 | D27: 147636 | E27: 14764 | F27: 알바몬 유료 서비스
A28: 2017-11-15 | B28: (주)아마존카 | C28: 446600 | D28: 406000 | E28: 40600 | F28: 45회차 대여료
A29: 2017-11-30 | B29: S.O.M 서비스(ShareOne'sMan services) | C29: 22000000 | D29: 20000000 | E29: 2000000 | F29: 일용비
A30: 2017-12-15 | B30: (주)아마존카 | C30: 446600 | D30: 406000 | E30: 40600 | F30: 46회차 대여료 | G30: 2017년
A31: 2017-12-20 | B31: 잡코리아 유한책임회사 | C31: -217000 | D31: -197273 | E31: -19727 | F31: [알바몬] 유료서비스 | G31: 합계금액 | H31: 공급가액 | I31: 세액
A32: 2017-12-20 | B32: 잡코리아 유한책임회사 | C32: -78200 | D32: -71091 | E32: -7109 | F32: [알바몬] 유료서비스 | G32: =SUM(C6:C32) -> 48530080 | H32: =SUM(D6:D32) -> 44118255 | I32: =SUM(E6:E32) -> 4411825
A33: 2018-01-11 | B33: 조은커뮤니케이션 | C33: 27500 | D33: 25000 | E33: 2500 | F33: 프린터임대료
A34: 2018-01-15 | B34: (주)아마존카 | C34: 446600 | D34: 406000 | E34: 40600 | F34: 47회차 대여료
A35: 2018-02-06 | B35: 성주이씨판윤공종회（가든타워 지점） | C35: 550000 | D35: 500000 | E35: 50000 | F35: 임대료
A36: 2018-02-11 | B36: 조은커뮤니케이션 | C36: 27500 | D36: 25000 | E36: 2500 | F36: 프린터임대료
A37: 2018-02-12 | B37: (주)코스콤 | C37: 55000 | D37: 50000 | E37: 5000 | F37: 공인인증서발급
A38: 2018-02-15 | B38: (주)아마존카 | C38: 446600 | D38: 406000 | E38: 40600 | F38: 48회차 대여료
A39: 2018-03-06 | B39: 성주이씨판윤공종회（가든타워 지점） | C39: 550000 | D39: 500000 | E39: 50000 | F39: 임대료
A40: 2018-03-09 | B40: 피씨엔진 | C40: 660000 | D40: 600000 | E40: 60000 | F40: 중고 모니터, PC
...

Sheet ★☆★☆★
A1: 46101
A2: 미입금계산서 | B2: 합계 | C2: 공급 | D2: 세액 | I2: 카드에서 매입금액 + | J2: (-) 가 납부할금액
B3: ='미입금(휴먼)'!D2 -> 27002375 | C3: ='미입금(휴먼)'!E2 -> 25000770 | D3: ='미입금(휴먼)'!F2 -> 2001605 | F3: 부가세 | H3: 매출 | I3: 매입 | J3: 계 (매입-매출) | K3: 매입정정 | L3: 부가세납부금액
F4: 2024년 | G4: 1~12월 | H4: 497534662 | I4: 133127272 | J4: -364471410 | L4: 364471410 | M4: 2024년
B5: 합계 | C5: 공급 | D5: 세액 | F5: 2025년 | G5: 1~3월 | H5: 114878031 | I5: 56719521 | J5: -58158510 | L5: =58158510 -> 58158510
A6: 2024년 | B6: ='매출(휴먼)'!I3961+'매출(휴먼)'!I3902+'매출(휴먼)'!I3846+'매출(휴먼)'!I3805+'매출(휴먼)'!I3754+'매출(휴먼)'!I3709+'매출(휴먼)'!I3664+'매출(휴먼)'!I3615+'매출(휴먼)'!I3567+'매출(휴먼)'!I3521+'매출(휴먼)'!I3472+'매출(휴먼)'!I3426 -> 5818001769 | C6: ='매출(휴먼)'!J3961+'매출(휴먼)'!J3902+'매출(휴먼)'!J3846+'매출(휴먼)'!J3805+'매출(휴먼)'!J3754+'매출(휴먼)'!J3709+'매출(휴먼)'!J3664+'매출(휴먼)'!J3615+'매출(휴먼)'!J3567+'매출(휴먼)'!J3521+'매출(휴먼)'!J3472+'매출(휴먼)'!J3426 -> 5324478103 | D6: ='매출(휴먼)'!K3961+'매출(휴먼)'!K3902+'매출(휴먼)'!K3846+'매출(휴먼)'!K3805+'매출(휴먼)'!K3754+'매출(휴먼)'!K3709+'매출(휴먼)'!K3664+'매출(휴먼)'!K3615+'매출(휴먼)'!K3567+'매출(휴먼)'!K3521+'매출(휴먼)'!K3472+'매출(휴먼)'!K3426 -> 493523666 | G6: 4~6월 | H6: 37373919 | I6: 5261299 | J6: =-32312720-186760-46070-6180 -> -32551730 | L6: =18000000+3490790+10186870 -> 31677660 | M6: 2/27, 3/16, 3/19 | N6: =J6+L6 -> -874070
A7: 2025년 | B7: ='매출(휴먼)'!I4237+'매출(휴먼)'!I4218+'매출(휴먼)'!I4199+'매출(휴먼)'!I4182+'매출(휴먼)'!I4161+'매출(휴먼)'!I4144+'매출(휴먼)'!I4131+'매출(휴먼)'!I4122+'매출(휴먼)'!I4112+'매출(휴먼)'!I4097+'매출(휴먼)'!I4055+'매출(휴먼)'!I4005 -> 3902546135 | C7: ='매출(휴먼)'!J4237+'매출(휴먼)'!J4218+'매출(휴먼)'!J4199+'매출(휴먼)'!J4182+'매출(휴먼)'!J4161+'매출(휴먼)'!J4144+'매출(휴먼)'!J4131+'매출(휴먼)'!J4122+'매출(휴먼)'!J4112+'매출(휴먼)'!J4097+'매출(휴먼)'!J4055+'매출(휴먼)'!J4005 -> 3563807712 | D7: ='매출(휴먼)'!K4237+'매출(휴먼)'!K4218+'매출(휴먼)'!K4199+'매출(휴먼)'!K4182+'매출(휴먼)'!K4161+'매출(휴먼)'!K4144+'매출(휴먼)'!K4131+'매출(휴먼)'!K4122+'매출(휴먼)'!K4112+'매출(휴먼)'!K4097+'매출(휴먼)'!K4055+'매출(휴먼)'!K4005 -> 338738423 | G7: 7~9월 | H7: 92090052 | I7: 65588142 | J7: =-27463940-161840-98260-17340 -> -27741380
A8: 2026년 1월 | B8: ='매출(휴먼)'!I4249 -> 296082731 | C8: ='매출(휴먼)'!J4249 -> 269618612 | D8: ='매출(휴먼)'!K4249 -> 26464119 | G8: 10~12월 | H8: 111898832 | I8: 26720911 | J8: =-85230490-693770 -> -85924260
A9: 2026년 2월 | B9: ='매출(휴먼)'!I4261 -> 306137986 | C9: ='매출(휴먼)'!J4261 -> 278760606 | D9: ='매출(휴먼)'!K4261 -> 27377380 | H9: =SUM(H5:H8) -> 356240834 | I9: =SUM(I5:I8) -> 154289873 | J9: =SUM(J5:J8) -> -204375880 | K9: =SUM(J4:L8) -> -114539710
A10: 2026년 3월 | B10: ='매출(휴먼)'!I4274 -> 106640736 | C10: ='매출(휴먼)'!J4274 -> 97399280 | D10: ='매출(휴먼)'!K4274 -> 9241456 | F10: 2026년 | G10: 1~3월 | H10: ='매출(휴먼)'!K4249+'매출(휴먼)'!K4261+'매출(휴먼)'!K4274 -> 63082955 | I10: =SUM('매입계산서(휴먼)'!E1023:E1113) -> 44796429 | J10: =I10-H10 -> -18286526
A11: 2026년 4월 | G11: 4~6월
A12: 2026년 5월 | G12: 7~9월
A13: 2026년 6월 | G13: 10~12월
A14: 2026년 7월 | H14: =SUM(H10:H13) -> 63082955 | I14: =SUM(I10:I13) -> 44796429 | J14: =SUM(J10:J13) -> -18286526 | K14: =SUM(J10:L13) -> -18286526
A15: 2026년 8월 | H15: 주차포함
A16: 2026년 9월
A17: 2026년 10월 | G17: 미입금계산서합계액(공급+세액) | H17: =B3 -> 27002375
A18: 2026년 11월 | G18: 통장잔고 | H18: ='3월'!J1 -> -39575875
A19: 2026년 12월 | E19: 일용 | F19: 미청구(공급가액) | H19: =SUM(H17:H18) -> -12573500
A20: ** 수기작성 ** | B20: 인건비지급액 | C20: 차액(청구-지급) | F20: 64118000 | G20: 미청구액 | H20: =(F20+F21)*1.1 -> 70529800 | I20: 미청구공급가+10%
A21: 1월 | B21: =SUM(B66:C66) -> 247411052 | C21: =F66-B21 -> 22798641 | G21: 부가세 | H21: =SUM(K9+K14) -> -132826236
A22: 2월 | B22: =SUM(B67:C67) -> 251919726 | C22: =F67-B22 -> 26840880 | H22: =SUM(H19:H21) -> -74869936
A23: 3월 | B23: =SUM(B68:C68) -> 128598560 | C23: =F68+F20-B23 -> 42160176
B25: 이익금 | F25: 신고
B26: 인건비 | C26: 대체 (강남세브,용인세브,연세의료원,피앤케이) | D26: 차액 | F26: 매출(공급가액) | G26: 매입(신고+매입공급+급여) | H26: 매출-매입 | I26: 이상이익율(7%) | K26: 신고금액 | L26: 매입금액 | M26: 직원급여
A27: 2023년 1월 | B27: =#REF! -> #REF! | C27: =#REF!+#REF!+#REF! -> #REF! | D27: =F27-(B27+C27) -> #REF! | F27: ='매출(휴먼)'!J2784 -> 305389386 | G27: =SUM(K27:M27) -> #REF! | H27: =F27-G27 -> #REF! | I27: =F27*7% -> 21377257 | J27: =H27-I27 -> #REF! | K27: =B27+C27 -> #REF! | L27: =SUM('[1]매입계산서(채움)'!D400:D410) -> #REF! | M27: ='월별사용내역'!R87 -> 19600000 | N27: 1월
A28: 2월 | B28: =#REF! -> #REF! | C28: =#REF!+#REF!+#REF! -> #REF! | D28: =F28-(B28+C28) -> #REF! | F28: ='매출(휴먼)'!J2836 -> 255106371 | G28: =SUM(K28:M28) -> #REF! | H28: =F28-G28 -> #REF! | I28: =F28*7% -> 17857446 | J28: =H28-I28 -> #REF! | K28: =B28+C28 -> #REF! | L28: =SUM('[1]매입계산서(채움)'!D411:D418) -> #REF! | M28: ='월별사용내역'!R88 -> 20000000 | N28: 2월
A29: 3월 | B29: =#REF! -> #REF! | C29: =#REF!+#REF!+#REF! -> #REF! | D29: =F29-(B29+C29) -> #REF! | F29: ='매출(휴먼)'!J2888 -> 284243190 | G29: =SUM(K29:M29) -> #REF! | H29: =F29-G29 -> #REF! | I29: =F29*7% -> 19897023 | J29: =H29-I29 -> #REF! | K29: =B29+C29 -> #REF! | L29: =SUM('[1]매입계산서(채움)'!D419:D433) -> #REF! | M29: ='월별사용내역'!R89 -> 20658340 | N29: 3월
A30: 4월 | B30: =#REF! -> #REF! | C30: =#REF!+#REF!+#REF! -> #REF! | D30: =F30-(B30+C30) -> #REF! | F30: ='매출(휴먼)'!J2938 -> 295389880 | G30: =SUM(K30:M30) -> #REF! | H30: =F30-G30 -> #REF! | I30: =F30*7% -> 20677292 | J30: =H30-I30 -> #REF! | K30: =B30+C30 -> #REF! | L30: =SUM('[1]매입계산서(채움)'!D434:D445) -> #REF! | M30: ='월별사용내역'!R90 -> 10900000 | N30: 4월
A31: 5월 | B31: =#REF! -> #REF! | C31: =#REF!+#REF!+#REF! -> #REF! | D31: =F31-(B31+C31) -> #REF! | F31: ='매출(휴먼)'!J2988 -> 354306200 | G31: =SUM(K31:M31) -> #REF! | H31: =F31-G31 -> #REF! | I31: =F31*7% -> 24801434 | J31: =H31-I31 -> #REF! | K31: =B31+C31 -> #REF! | L31: =SUM('[1]매입계산서(채움)'!D446:D453) -> #REF! | M31: ='월별사용내역'!R91 -> 15600000 | N31: 5월
A32: 6월 | B32: =#REF! -> #REF! | C32: =#REF!+#REF!+#REF! -> #REF! | D32: =F32-(B32+C32) -> #REF! | F32: ='매출(휴먼)'!J3054 -> 335424790 | G32: =SUM(K32:M32) -> #REF! | H32: =F32-G32 -> #REF! | I32: =F32*7% -> 23479735 | J32: =H32-I32 -> #REF! | K32: =B32+C32 -> #REF! | L32: =SUM('[1]매입계산서(채움)'!D454:D465) -> #REF! | M32: ='월별사용내역'!R92 -> 13354270 | N32: 6월
A33: 7월 | B33: =#REF! -> #REF! | C33: =#REF!+#REF!+#REF! -> #REF! | D33: =F33-(B33+C33) -> #REF! | F33: ='매출(휴먼)'!J3111 -> 349793060 | G33: =SUM(K33:M33) -> #REF! | H33: =F33-G33 -> #REF! | I33: =F33*7% -> 24485514 | J33: =H33-I33 -> #REF! | K33: =B33+C33 -> #REF! | L33: =SUM('[1]매입계산서(채움)'!D466:D479) -> #REF! | M33: ='월별사용내역'!R93 -> 15877620 | N33: 7월
A34: 8월 | B34: =#REF! -> #REF! | C34: =#REF!+#REF!+#REF! -> #REF! | D34: =F34-(B34+C34) -> #REF! | F34: ='매출(휴먼)'!J3163 -> 387148781 | G34: =SUM(K34:M34) -> #REF! | H34: =F34-G34 -> #REF! | I34: =F34*7% -> 27100415 | J34: =H34-I34 -> #REF! | K34: =B34+C34 -> #REF! | L34: =SUM('[1]매입계산서(채움)'!D480:D487) -> #REF! | M34: ='월별사용내역'!R94 -> 15700000 | N34: 8월
A35: 9월 | B35: =#REF! -> #REF! | C35: =#REF!+#REF!+#REF! -> #REF! | D35: =F35-(B35+C35) -> #REF! | F35: ='매출(휴먼)'!J3213 -> 305326350 | G35: =SUM(K35:M35) -> #REF! | H35: =F35-G35 -> #REF! | I35: =F35*7% -> 21372844 | J35: =H35-I35 -> #REF! | K35: =B35+C35 -> #REF! | L35: =SUM('[1]매입계산서(채움)'!D488:D503) -> #REF! | M35: ='월별사용내역'!R95 -> 16250000 | N35: 9월
A36: 10월 | B36: =#REF! -> #REF! | C36: =#REF!+#REF!+#REF! -> #REF! | D36: =F36-(B36+C36) -> #REF! | F36: ='매출(휴먼)'!J3265 -> 336582300 | G36: =SUM(K36:M36) -> #REF! | H36: =F36-G36 -> #REF! | I36: =F36*7% -> 23560761 | J36: =H36-I36 -> #REF! | K36: =B36+C36 -> #REF! | L36: =SUM('[1]매입계산서(채움)'!D504:D518) -> #REF! | M36: ='월별사용내역'!R96 -> 13100000 | N36: 10월
A37: 11월 | B37: =#REF! -> #REF! | C37: =#REF!+#REF!+#REF! -> #REF! | D37: =F37-(B37+C37) -> #REF! | F37: ='매출(휴먼)'!J3315 -> 313027650 | G37: =SUM(K37:M37) -> #REF! | H37: =F37-G37 -> #REF! | I37: =F37*7% -> 21911936 | J37: =H37-I37 -> #REF! | K37: =B37+C37 -> #REF! | L37: =SUM('[1]매입계산서(채움)'!D519:D526) -> #REF! | M37: ='월별사용내역'!R97 -> 13400000 | N37: 11월
A38: 12월 | B38: =#REF! -> #REF! | C38: =#REF!+#REF!+#REF!+#REF! -> #REF! | D38: =F38-(B38+C38) -> #REF! | F38: ='매출(휴먼)'!J3373 -> 605812230 | G38: =SUM(K38:M38) -> #REF! | H38: =F38-G38 -> #REF! | I38: =F38*7% -> 42406856 | J38: =H38-I38 -> #REF! | K38: =B38+C38 -> #REF! | L38: =SUM('[1]매입계산서(채움)'!D527:D539) -> #REF! | M38: ='월별사용내역'!R98 -> 13300000 | N38: 12월
B39: 일용+경비지도사 | C39: 유령 | G39: 일용신고,매입계산서,직원급여 | I39: 부족신고금액 | J39: =SUM(J27:J38) -> #REF!
A40: 2024년 1월 | B40: =#REF!+#REF!+#REF! -> #REF! | C40: =#REF!+#REF!+#REF!+#REF! -> #REF! | D40: =F40-(B40+C40) -> #REF! | F40: ='매출(휴먼)'!J3426 -> 353878670 | G40: =SUM(K40:M40) -> #REF! | H40: =F40-G40 -> #REF! | I40: =F40*7% -> 24771507 | J40: =H40-I40 -> #REF! | K40: =B40+C40 -> #REF! | L40: =SUM('매입계산서(휴먼)'!D579:D591) -> 162427363 | M40: ='월별사용내역'!R100 -> 13600000 | N40: 1월
A41: 2월 | B41: =#REF! -> #REF! | C41: =#REF!+#REF!+#REF!+#REF! -> #REF! | D41: =F41-(B41+C41) -> #REF! | F41: ='매출(휴먼)'!J3472 -> 317366392 | G41: =SUM(K41:M41) -> #REF! | H41: =F41-G41 -> #REF! | I41: =F41*7% -> 22215647 | J41: =H41-I41 -> #REF! | K41: =B41+C41 -> #REF! | L41: =SUM('매입계산서(휴먼)'!D592:D607) -> 345485696 | M41: ='월별사용내역'!R101 -> 23141937 | N41: 2월
...

Sheet 3월
A1: 날짜 | B1: 적요 | C1: 입금액(원) | D1: 출금액(원) | E1: 잔액(원) | F1: 계산서발행일 | G1: 계좌 | I1: 통장잔고 | J1: =L1+N1+P1+R1+T1+V1 -> -39575875 | K1: 기업 | L1: 1073854 | M1: 하나 | N1: =508880+445282 -> 954162 | O1: 우리 | P1: -41705207 | Q1: 신한 | R1: 101316 | S1: 농협 | T1: 0 | U1: 국민
A2: 전월이월 | E2: -50446141
A3: 46082 | B3: 대출이자원가 | D3: 442452 | E3: =E2+C3-D3 -> -50888593 | G3: 우리
B4: 인건비 | D4: 162460 | E4: =E3+C4-D4 -> -51051053 | G4: 우리
A5: 46083 | B5: 인건비 | D5: 162460 | E5: =E4+C5-D5 -> -51213513 | G5: 우리
A6: 46084 | B6: 311202934129 | D6: 2175285 | E6: =E5+C6-D6 -> -53388798 | G6: 신한
B7: 중진공대출 | D7: 4391409 | E7: =E6+C7-D7 -> -57780207 | G7: 신한
B8: 다보스 주차비 | C8: 274010 | E8: =E7+C8-D8 -> -57506197 | G8: 하나
B9: 주식회사 쏘카 | C9: 440000 | E9: =E8+C9-D9 -> -57066197 | G9: 하나
B10: 1220600815590 | D10: 1364653 | E10: =E9+C10-D10 -> -58430850 | G10: 우리
A11: 46085 | B11: 다보스 주차비 | C11: 450050 | E11: =E10+C11-D11 -> -57980800 | G11: 하나
B12: (주)휴먼엠에 | D12: 30300 | E12: =E11+C12-D12 -> -58011100 | G12: 하나
B13: (의)영문의료재단 | D13: 312000 | E13: =E12+C13-D13 -> -58323100 | G13: 하나
B14: 최영창 | D14: 240000 | E14: =E13+C14-D14 -> -58563100 | F14: 컨설팅비용부가세 | G14: 하나
B15: (주)삼구아이앤씨-소노벨 룸메이드 | C15: 50773250 | E15: =E14+C15-D15 -> -7789850.3 | F15: 46075 | G15: 우리
B16: (주)삼구아이앤씨-소노캄 룸메이드 | C16: 14790050 | E16: =E15+C16-D16 -> 7000199.7 | F16: 46075 | G16: 우리
B17: 이경미 | D17: 48200000 | E17: =E16+C17-D17 -> -41199800 | G17: 우리
B18: 주식회사 우림 | D18: 14790050 | E18: =E17+C18-D18 -> -55989850 | G18: 우리
A19: 46086 | B19: 다보스 주차비 | C19: 1034344 | E19: =E18+C19-D19 -> -54955506 | G19: 하나
B20: 인건비 | D20: 42550 | E20: =E19+C20-D20 -> -54998056 | G20: 우리
A21: 46087 | B21: 다보스 주차비 | C21: 431151 | E21: =E20+C21-D21 -> -54566905 | G21: 하나
B22: 인건비 | D22: 42550 | E22: =E21+C22-D22 -> -54609455 | G22: 우리
A23: 46088 | B23: 인건비 | D23: 292040 | E23: =E22+C23-D23 -> -54901495 | G23: 우리
A24: 46089 | B24: 인건비 | D24: 181800 | E24: =E23+C24-D24 -> -55083295 | G24: 우리
A25: 46090 | B25: 다보스 주차비 | C25: 353551 | E25: =E24+C25-D25 -> -54729744 | G25: 하나
B26: 75698007209642-00001 | D26: 758837 | E26: =E25+C26-D26 -> -55488581 | G26: 하나
B27: 조은커뮤니-H | D27: 38500 | E27: =E26+C27-D27 -> -55527081 | G27: 하나
B28: 이경미 | D28: 1000000 | E28: =E27+C28-D28 -> -56527081 | G28: 우리
A29: 46091 | B29: 다보스 주차비 | C29: 404189 | E29: =E28+C29-D29 -> -56122892 | G29: 하나
B30: 이경미 | C30: 23000000 | E30: =E29+C30-D30 -> -33122892 | G30: 하나
B31: 김동빈-다보스 인건비 | D31: 96700 | E31: =E30+C31-D31 -> -33219592 | G31: 하나
B32: 다보스 급여 | D32: 11304140 | E32: =E31+C32-D32 -> -44523732 | G32: 하나
B33: 2/21~말일 케이엠파크 미지급급여 | D33: 13113030 | E33: =E32+C33-D33 -> -57636762 | G33: 하나
B34: SMS수수료 | D34: 900 | E34: =E33+C34-D34 -> -57637662 | G34: 우리
B35: 이경미 | C35: 24000000 | E35: =E34+C35-D35 -> -33637662 | G35: 기업
B36: SMS통지수수료 | D36: 900 | E36: =E35+C36-D36 -> -33638562 | G36: 기업
B37: 직원급여(고선옥,허다경,전가희) | D37: 8300000 | E37: =E36+C37-D37 -> -41938562 | G37: 기업
B38: 완도급여(2명) | D38: 4897760 | E38: =E37+C38-D38 -> -46836322 | G38: 기업
B39: 한국보육진흥원급여(2명) | D39: 2722110 | E39: =E38+C39-D39 -> -49558432 | G39: 기업
B40: 박준식 | D40: 200000 | E40: =E39+C40-D40 -> -49758432 | G40: 기업
...

Sheet 2월
A1: 날짜 | B1: 적요 | C1: 입금액(원) | D1: 출금액(원) | E1: 잔액(원) | F1: 계산서발행일 | G1: 계좌 | I1: 통장잔고 | J1: =L1+N1+P1+R1+T1+V1 -> -50446141 | K1: 기업 | L1: 248264 | M1: 하나 | N1: =387218+218260 -> 605478 | O1: 우리 | P1: -57967893 | Q1: 신한 | R1: 6668010 | S1: 농협 | T1: 0 | U1: 국민
A2: 전월이월 | E2: -60314464
A3: 46054 | B3: 대출이자원가 | D3: 15200 | E3: =E2+C3-D3 -> -60329664 | G3: 우리
B4: 이체수수료 | D4: 500 | E4: =E3+C4-D4 -> -60330164 | G4: 농협
B5: 이경미 | D5: 1500000 | E5: =E4+C5-D5 -> -61830164 | G5: 기업
B6: 인건비 | D6: 162460 | E6: =E5+C6-D6 -> -61992624 | G6: 기업
A7: 46055 | B7: 다보스 주차비 | C7: 521751 | E7: =E6+C7-D7 -> -61470873 | G7: 하나
B8: 주식회사 쏘카 | C8: 440000 | E8: =E7+C8-D8 -> -61030873 | G8: 하나
B9: 인건비 | D9: 61890 | E9: =E8+C9-D9 -> -61092763 | G9: 기업
A10: 46056 | B10: 다보스 주차비 | C10: 490965 | E10: =E9+C10-D10 -> -60601798 | G10: 하나
B11: 이혜경(파주 오입금 예상) | C11: 110000 | E11: =E10+C11-D11 -> -60491798 | G11: 하나
A12: 46057 | B12: 대출이자지급 | D12: 566543 | E12: =E11+C12-D12 -> -61058341 | G12: 우리
B13: (주)삼구아이앤씨-소노캄 룸메이드 | C13: 4294290 | E13: =E12+C13-D13 -> -56764051 | F13: 46047 | G13: 우리
B14: 신한주식회사 우림 | D14: 4294290 | E14: =E13+C14-D14 -> -61058341 | G14: 우리
B15: 교통범칙금납부 | D15: 40000 | E15: =E14+C15-D15 -> -61098341 | G15: 기업
B16: 용마터널주식회사０２ | D16: 20400 | E16: =E15+C16-D16 -> -61118741 | G16: 기업
B17: 다보스 주차비 | C17: 1056422 | E17: =E16+C17-D17 -> -60062319 | G17: 하나
B18: 김영민(파주 오입금 예상) | C18: 35000 | E18: =E17+C18-D18 -> -60027319 | G18: 하나
A19: 46058 | B19: 다보스 주차비 | C19: 459970 | E19: =E18+C19-D19 -> -59567349 | G19: 하나
A20: 46059 | B20: 다보스 주차비 | C20: 318819 | E20: =E19+C20-D20 -> -59248530 | G20: 하나
B21: (주)삼구아이앤씨-소노벨 룸메이드 | C21: 35537260 | E21: =E20+C21-D21 -> -23711270 | F21: 46054 | G21: 우리
B22: 주식회사 우림 | D22: 31147600 | E22: =E21+C22-D22 -> -54858870 | G22: 우리
B23: 이경미 | D23: 1500000 | E23: =E22+C23-D23 -> -56358870 | G23: 우리
B24: 인건비 | D24: 61890 | E24: =E23+C24-D24 -> -56420760 | G24: 우리
A25: 46060 | B25: 인건비 | D25: 282370 | E25: =E24+C25-D25 -> -56703130 | G25: 우리
A26: 46061 | B26: 인건비 | D26: 162460 | E26: =E25+C26-D26 -> -56865590 | G26: 우리
A27: 46062 | B27: KB라이프생명 | C27: 2236911 | E27: =E26+C27-D27 -> -54628679 | F27: 약관대출 | G27: 기업
B28: 다보스 주차비 | C28: 436526 | E28: =E27+C28-D28 -> -54192153 | G28: 하나
B29: 조은커뮤니-H | D29: 38500 | E29: =E28+C29-D29 -> -54230653 | G29: 하나
B30: 이승상 | D30: 100000 | E30: =E29+C30-D30 -> -54330653 | F30: 다보스병원 미끄럼사고 KB 손해보험 자기부담금 | G30: 하나
B31: 75698007209642-00001 | D31: 840142 | E31: =E30+C31-D31 -> -55170795 | G31: 하나
B32: 김영민 | D32: 35000 | E32: =E31+C32-D32 -> -55205795 | F32: 2/4 오입금분 반환지급 | G32: 하나
B33: 삼성생명보험 | C33: 5000000 | E33: =E32+C33-D33 -> -50205795 | F33: 약관대출 | G33: 우리
A34: 46063 | B34: 다보스 주차비 | C34: 513002 | E34: =E33+C34-D34 -> -49692793 | G34: 하나
B35: 1/21~말일 케이엠파크 미지급급여 | D35: 19665770 | E35: =E34+C35-D35 -> -69358563 | G35: 하나
B36: 다보스 급여 | D36: 11904940 | E36: =E35+C36-D36 -> -81263503 | G36: 하나
B37: (의)영문의료재단 | D37: 432000 | E37: =E36+C37-D37 -> -81695503 | G37: 하나
B38: 최성수-다보스 인건비 | D38: 386800 | E38: =E37+C38-D38 -> -82082303 | G38: 하나
B39: 김동빈-다보스 인건비 | D39: 386800 | E39: =E38+C39-D39 -> -82469103 | G39: 하나
B40: 조창희-다보스 인건비 | D40: 145050 | E40: =E39+C40-D40 -> -82614153 | G40: 하나
...

Sheet 1월
A1: 날짜 | B1: 적요 | C1: 입금액(원) | D1: 출금액(원) | E1: 잔액(원) | F1: 계산서발행일 | G1: 계좌 | I1: 통장잔고 | J1: =L1+N1+P1+R1+T1+V1 -> -60314464 | K1: 기업 | L1: 919660 | M1: 하나 | N1: =38524+713552 -> 752076 | O1: 우리 | P1: -63084800 | Q1: 신한 | R1: 168010 | S1: 농협 | T1: 930590 | U1: 국민
A2: 전월이월 | E2: -56067066
A3: 46023 | B3: 파주 주차비 | C3: 42100 | E3: =E2+C3-D3 -> -56024966 | G3: 하나
B4: 인건비 | D4: 162460 | E4: =E3+C4-D4 -> -56187426 | G4: 기업
A5: 46024 | B5: 다보스 주차비 | C5: 456982 | E5: =E4+C5-D5 -> -55730444 | G5: 하나
B6: 파주 주차비 | C6: 276346 | E6: =E5+C6-D6 -> -55454098 | G6: 하나
B7: 주식회사 쏘카 | C7: 440000 | E7: =E6+C7-D7 -> -55014098 | G7: 하나
B8: 국민윤희중-다보스 인건비 | D8: 241750 | E8: =E7+C8-D8 -> -55255848 | G8: 우리
B9: 농협한승철-다보스 인건비 | D9: 193400 | E9: =E8+C9-D9 -> -55449248 | G9: 우리
B10: 신한김동영-파주 인건비 | D10: 483500 | E10: =E9+C10-D10 -> -55932748 | G10: 우리
B11: 신한황태원(황태원)-다보스 생수 | D11: 28600 | E11: =E10+C11-D11 -> -55961348 | G11: 우리
B12: 농협한전(문산분회)-파주 전기요금 | D12: 122190 | E12: =E11+C12-D12 -> -56083538 | G12: 우리
B13: 농협이가영-금촌 식대 | D13: 37000 | E13: =E12+C13-D13 -> -56120538 | G13: 우리
B14: 인건비 | D14: 1764810 | E14: =E13+C14-D14 -> -57885348 | G14: 기업
A15: 46025 | B15: 파주 주차비 | C15: 1000 | E15: =E14+C15-D15 -> -57884348 | G15: 하나
B16: 인건비 | D16: 181800 | E16: =E15+C16-D16 -> -58066148 | G16: 기업
A17: 46026 | B17: 인건비 | D17: 162460 | E17: =E16+C17-D17 -> -58228608 | G17: 기업
A18: 46027 | B18: (주)삼구아이앤씨-소노벨 룸메이드 | C18: 34674420 | E18: =E17+C18-D18 -> -23554188 | F18: 46019 | G18: 우리
B19: 이경미 | D19: 26500000 | E19: =E18+C19-D19 -> -50054188 | G19: 우리
B20: 다보스 주차비 | C20: 413892 | E20: =E19+C20-D20 -> -49640296 | G20: 하나
B21: 파주 주차비 | C21: 128185 | E21: =E20+C21-D21 -> -49512111 | G21: 하나
A22: 46028 | B22: 다보스 주차비 | C22: 688049 | E22: =E21+C22-D22 -> -48824062 | G22: 하나
B23: 파주 주차비 | C23: 75791 | E23: =E22+C23-D23 -> -48748271 | G23: 하나
B24: 도봉（２１０） | D24: 6000000 | E24: =E23+C24-D24 -> -54748271 | F24: 부가가치세 납부 | G24: 기업
A25: 46029 | B25: 다보스 주차비 | C25: 1032797 | E25: =E24+C25-D25 -> -53715474 | G25: 하나
B26: 파주 주차비 | C26: 2164 | E26: =E25+C26-D26 -> -53713310 | G26: 하나
A27: 46030 | B27: 다보스 주차비 | C27: 361108 | E27: =E26+C27-D27 -> -53352202 | G27: 하나
B28: 75698007209642-00001 | D28: 748756 | E28: =E27+C28-D28 -> -54100958 | F28: 대출이자 | G28: 하나
A29: 46031 | B29: (주)삼구아이앤씨 | C29: 49743045 | E29: =E28+C29-D29 -> -4357913.3 | F29: 46026 | G29: 우리
B30: (주)삼구아이앤씨 | C30: 7353918 | E30: =E29+C30-D30 -> 2996004.7 | F30: 46026 | G30: 우리
B31: 주식회사 우림 | D31: 55816618 | E31: =E30+C31-D31 -> -52820613 | F31: 소노벨, 소노캄 | G31: 우리
B32: 토뱅최원희-다보스 인건비 | D32: 48350 | E32: =E31+C32-D32 -> -52868963 | G32: 우리
B33: 국민윤희중-다보스 인건비 | D33: 145050 | E33: =E32+C33-D33 -> -53014013 | G33: 우리
B34: 다보스 주차비 | C34: 355533 | E34: =E33+C34-D34 -> -52658480 | G34: 하나
B35: 조은커뮤니-H | D35: 38500 | E35: =E34+C35-D35 -> -52696980 | G35: 하나
B36: 이경미 | C36: 13000000 | E36: =E35+C36-D36 -> -39696980 | G36: 기업
A37: 46032 | B37: 12/21~말일 케이엠파크 미지급급여 | D37: 8246190 | E37: =E36+C37-D37 -> -47943170 | G37: 우리
B38: 소재덕? | D38: 91865 | E38: =E37+C38-D38 -> -48035035 | G38: 우리
B39: 완도급여(2명) | D39: 4168940 | E39: =E38+C39-D39 -> -52203975 | G39: 기업
B40: 박준식-경비수수료 | D40: 200000 | E40: =E39+C40-D40 -> -52403975 | G40: 기업
...

Sheet 월별사용내역
A1: ** 입금액은 부가세포함가 입니다 / 추후 세금납부시 지출로 잡을예정입니다 ** | AC1: ** 수입, 지출에 포함안됨 **
B2: 수입(A) | C2: 지출(B) | D2: 차액(A-B) | E2: 수입세부(A) | K2: 지출세부(B) | AC2: 대표님( * - 가 수입)
E3: 업체입금 | F3: 통장(이자,개설비) | G3: 환급or반환, 지원금 | H3: 대출 | I3: 하랑(좋은입금) | J3: 세무대체 차액 | K3: 인건비(대체포함) | L3: 업체지급 | M3: 외국인 | N3: 하랑엠에스 | O3: 세무대체자 | P3: 세금 | Q3: 4대보험료 | R3: 직원급여(퇴직금포함) | S3: 임원급여 | T3: 파견직급여 | U3: 적금 | V3: 보험료 | W3: 대출상환 | X3: 광고비 | Y3: 카드 | Z3: 기타운영비(렌트비, 기장료, 수수료, 보증금, 임대료, 비품, 소모품, 직원경조사 등등..) | AA3: 도급용역비용 | AC3: 입금 | AD3: 출금 | AE3: 차액
A4: 2016년 9월 | B4: 23461245 | C4: 29874835 | D4: -6413590 | E4: 23451230 | F4: 10015 | K4: 29866035 | Z4: 8800 | AC4: 12500000 | AD4: 4000000 | AF4: 9월
A5: 10월 | B5: 46107200 | C5: 41821195 | D5: 4286005 | E5: 46107200 | K5: 41310425 | Z5: 510770 | AC5: 7300000 | AD5: 12000000 | AF5: 10월
A6: 11월 | B6: 49971880 | C6: 43276585 | D6: 6695295 | E6: 49971880 | K6: 43014785 | P6: 107050 | Z6: 154750 | AC6: 12400000 | AD6: 20000000 | AF6: 11월
A7: 12월 | B7: 52773421 | C7: 46611054 | D7: 6162367 | E7: 52772040 | F7: 431 | G7: 950 | K7: 45504874 | P7: 352120 | Z7: 754060 | AC7: 23000000 | AD7: 25000000 | AF7: 12월
B8: 172313746 | C8: 161583669 | D8: 10730077 | E8: 172302350 | F8: 10446 | G8: 950 | H8: 0 | I8: 0 | J8: 0 | K8: 159696119 | L8: 0 | M8: 0 | N8: 0 | O8: 0 | P8: 459170 | Q8: 0 | R8: 0 | U8: 0 | Z8: 1428380 | AB8: 0 | AC8: 55200000 | AD8: 61000000 | AE8: 0
A9: 2017년 1월 | B9: 60655130 | C9: 37271562 | D9: 23383568 | E9: 60655130 | K9: 25592702 | P9: 7428090 | Q9: 3372240 | Z9: 878530 | AC9: 2000000 | AD9: 29800000 | AF9: 1월
A10: 2월 | B10: 27346280 | C10: 37427816 | D10: -10081536 | E10: 27336280 | F10: 10000 | K10: 27366715 | P10: 7477800 | Q10: 1023730 | Z10: 1559571 | AC10: 12500000 | AD10: 2000000 | AF10: 2월
A11: 3월 | B11: 37869798 | C11: 40083108 | D11: -2213310 | E11: 37525224 | F11: 534 | G11: 344040 | K11: 29896588 | P11: 200850 | Q11: 1419780 | Z11: 8565890 | AC11: 17400000 | AD11: 15500000 | AF11: 3월
A12: 4월 | B12: 173197292 | C12: 157294970 | D12: 15902322 | E12: 173092975 | G12: 104317 | K12: 141257223 | P12: 3536990 | Q12: 335410 | R12: 8470000 | Z12: 3695347 | AC12: 121200000 | AD12: 129200000 | AF12: 4월
A13: 5월 | B13: 159731154 | C13: 157249360 | D13: 2481794 | E13: 159731154 | K13: 133459155 | P13: 11238920 | Q13: 1480460 | R13: 6470500 | Z13: 4600325 | AC13: 123500000 | AD13: 129700000 | AF13: 5월
A14: 6월 | B14: 93708703 | C14: 82779175 | D14: 10929528 | E14: 93707234 | F14: 1469 | K14: 62192095 | P14: 751740 | Q14: 505570 | R14: 4800000 | Z14: 14529770 | AC14: 27700000 | AD14: 27700000 | AF14: 6월
A15: 7월 | B15: 63767497 | C15: 83087732 | D15: -19320235 | E15: 63767497 | K15: 54724758 | P15: 16136870 | Q15: 4909130 | R15: 2500000 | Z15: 4816974 | AC15: 25400000 | AD15: 19700000 | AE15: 5700000 | AF15: 7월
A16: 8월 | B16: 85115558 | C16: 83730027 | D16: 1385531 | E16: 85115558 | K16: 63614367 | P16: 8515530 | Q16: 3359750 | R16: 4300000 | Z16: 3940380 | AC16: 22000000 | AD16: 14000000 | AE16: 8000000 | AF16: 8월
A17: 9월 | B17: 154082015 | C17: 137956944 | D17: 16125071 | E17: 153924315 | F17: 900 | G17: 156800 | K17: 125434584 | P17: 131590 | Q17: 702670 | R17: 7500000 | Z17: 4188100 | AC17: 46650000 | AD17: 48000000 | AE17: -1350000 | AF17: 9월
A18: 10월 | B18: 134634961 | C18: 155441205 | D18: -20806244 | E18: 134474761 | G18: 160200 | K18: 108844845 | P18: 28967590 | Q18: 749390 | R18: 10230000 | Z18: 6649380 | AC18: 25300000 | AD18: 29150000 | AE18: -3850000 | AF18: 10월
A19: 11월 | B19: 137497607 | C19: 123303940 | D19: 14193667 | E19: 137419556 | G19: 78051 | K19: 96613300 | P19: 12994930 | Q19: 2171420 | R19: 6200000 | Z19: 5324290 | AC19: 37000000 | AD19: 50500000 | AE19: -13500000 | AF19: 11월
A20: 12월 | B20: 184681215 | C20: 176328577 | D20: 8352638 | E20: 184370774 | F20: 5606 | G20: 304835 | K20: 163238843 | P20: 630680 | Q20: 1659800 | R20: 5000000 | Z20: 5799254 | AC20: 60500000 | AD20: 66500000 | AE20: -6000000 | AF20: 12월
B21: 1312287210 | C21: 1271954416 | D21: 40332794 | E21: 1311120458 | F21: 18509 | G21: 1148243 | H21: 0 | I21: 0 | J21: 0 | K21: 1032235175 | L21: 0 | M21: 0 | N21: 0 | O21: 0 | P21: 98011580 | Q21: 21689350 | R21: 55470500 | U21: 0 | Z21: 64547811 | AB21: 0 | AC21: 521150000 | AD21: 561750000 | AE21: -11000000
A22: 2018년 1월 | B22: 234040202 | C22: 266016223 | D22: -31976021 | E22: 224040202 | G22: 10000000 | K22: 109553905 | M22: 48068203 | O22: 62670310 | P22: 30721910 | Q22: 1639100 | R22: 4247272 | Z22: 9115523 | AC22: 36500000 | AD22: 7000000 | AE22: 29500000 | AF22: 1월 | AG22: ← 내역에 포함안됨
A23: 2월 | B23: 216607884 | C23: 200936192 | D23: 15671692 | E23: 216048034 | G23: 559850 | K23: 103808931 | M23: 70234150 | P23: 14031950 | Q23: 324540 | R23: 5142741 | Z23: 7393880 | AC23: 20200000 | AD23: 27000000 | AE23: -6800000 | AF23: 2월 | AG23: 43353 | AH23: -30000000 | AI23: som→신한
A24: 3월 | B24: 203888066 | C24: 157701132 | D24: 46186934 | E24: 203876171 | F24: 11895 | K24: 71711985 | M24: 60798134 | P24: 10500220 | Q24: 1968060 | R24: 5290000 | Z24: 7432733 | AC24: 13000000 | AD24: 24700000 | AE24: -11700000 | AF24: 3월 | AG24: 43399 | AH24: -3000000 | AI24: som→신한
A25: 4월 | B25: 79247300 | C25: 126642631 | D25: -47395331 | E25: 77787300 | I25: 1460000 | K25: 66180165 | M25: 164390 | P25: 48400640 | Q25: 2086810 | R25: 4000000 | Z25: 5810626 | AC25: 19000000 | AD25: 14000000 | AE25: 5000000 | AF25: 4월 | AG25: 43405 | AH25: -3000000 | AI25: som→신한
A26: 5월 | B26: 192695108 | C26: 196049283 | D26: -3354175 | E26: 190729948 | G26: 1965160 | K26: 82806982 | M26: 32098685 | N26: 48450000 | P26: 9534390 | Q26: 10187270 | R26: 5750000 | Z26: 7221956 | AC26: 21500000 | AD26: 3500000 | AE26: 18000000 | AF26: 5월 | AG26: 43414 | AH26: 5000000 | AI26: 휴먼
A27: 6월 | B27: 187587186 | C27: 140787601 | D27: 46799585 | E27: 157578520 | F27: 8666 | H27: 30000000 | K27: 72566785 | M27: 47085000 | P27: 252540 | Q27: 6847540 | R27: 7600000 | Z27: 6435736 | AC27: 0 | AD27: 5500000 | AE27: -5500000 | AF27: 6월 | AG27: 43422 | AH27: 15000000 | AI27: 휴먼
A28: 7월 | B28: 178673590 | C28: 205926000 | D28: -27252410 | E28: 172931880 | F28: 560 | G28: 1355150 | J28: 4386000 | K28: 128466439 | M28: 51993675 | P28: 11356190 | Q28: 2470120 | R28: 5500000 | Z28: 6139576 | AD28: 7/3 | AE28: -17500000 | AG28: 43426 | AH28: -20000000 | AI28: 휴먼→신한
A29: 8월 | B29: 416314567 | C29: 389246355 | D29: 27068212 | E29: 416114413 | F29: 154 | G29: 200000 | K29: 263840756 | M29: 66874753 | P29: 31886090 | Q29: 2178090 | R29: 18500000 | Z29: 5966666 | AG29: 43442 | AH29: 5000000 | AI29: 휴먼
A30: 9월 | B30: 287649798 | C30: 231884029 | D30: 55765769 | E30: 286569730 | F30: 1319 | G30: 1078749 | K30: 129338232 | M30: 62568225 | P30: 15680910 | Q30: 6380690 | R30: 10316670 | Z30: 7599302 | AG30: 43497 | AH30: -5000000 | AI30: 우리→신한
A31: 10월 | B31: 258712113 | C31: 301934127 | D31: -43222014 | E31: 258688070 | F31: 22 | G31: 24021 | K31: 113470676 | M31: 71983642 | P31: 83909010 | Q31: 9267260 | R31: 8700000 | Z31: 14603539 | AG31: 43528 | AH31: -2000000 | AI31: 우리→신한
A32: 11월 | B32: 231777729 | C32: 221938991 | D32: 9838738 | E32: 230260970 | F32: 2 | G32: 1516757 | K32: 106725165 | M32: 79330793 | P32: 14103620 | Q32: 2091940 | R32: 11700000 | Z32: 7987473 | AB32: ** 2월세무대체자(김명자님) 50,683,000원중 50,150,000원은 재입금되어 533,000원만 지출잡음/ 3월 이계승님 49,317,000원중 49,000,000재입금. 317,000원만 지출잡음 | AG32: 43560 | AH32: -3000000 | AI32: 우리→신한
A33: 12월 | B33: 250548514 | C33: 245302359 | D33: 5246155 | E33: 250531100 | F33: 17414 | K33: 149567445 | M33: 71115555 | P33: 4019690 | Q33: 3322050 | R33: 9880000 | Z33: 7397619 | AB33: 휴먼 대체(우리계좌 or 신고불가) | AG33: 43633 | AH33: -5000000 | AI33: 좋은→신한
B34: 2737742057 | C34: 2684364923 | D34: 53377134 | E34: 2685156338 | F34: 40032 | G34: 16699687 | H34: 30000000 | I34: 1460000 | J34: 4386000 | K34: 1398037466 | L34: 0 | M34: 662315205 | N34: 48450000 | O34: 62670310 | P34: 274397160 | Q34: 48763470 | R34: 96626683 | U34: 0 | Z34: 93104629 | AB34: 0 | AC34: 110200000 | AD34: 81700000 | AE34: 11000000
A35: 2019년 1월 | B35: 344232324 | C35: 306071353 | D35: 38160971 | E35: 343898390 | F35: 53 | G35: 333881 | K35: 118300338 | M35: 82285237 | P35: 85674180 | Q35: 4500230 | R35: 3000000 | Z35: 12311368 | AB35: 171777000 | AC35: 우리-160,000,000/ 신준식-10,400,000/ 미성-1,377,000 | AG35: 43649 | AH35: -60000000 | AI35: 좋은-2천/ 휴먼-4천→신한
A36: 2월 | B36: 197112514 | C36: 157777213 | D36: 39335301 | E36: 197111618 | F36: 896 | K36: 99524465 | M36: 30684100 | O36: 533000 | P36: 3840660 | Q36: 3261460 | R36: 9984800 | Z36: 9948728 | AB36: 16440000 | AC36: 우리-20,000,000출금, 5,000,000입금/ 미성-1,440,000 // 참고(좋은-50,800,000 입/ 신준식-3,200,000출) | AG36: 43661 | AH36: -10000000 | AI36: 좋은→신한
A37: 3월 | B37: 125203434 | C37: 148886563 | D37: -23683129 | E37: 122749528 | F37: 3906 | G37: 2450000 | K37: 76496215 | M37: 36371686 | O37: 317000 | P37: 8313350 | Q37: 1764110 | R37: 13484800 | Z37: 12139402 | AC37: 휴먼가지급금 75,000,000원 | AG37: 43681 | AH37: 35000000 | AI37: 휴먼
A38: 4월 | B38: 171466527 | C38: 195661638 | D38: -24195111 | E38: 171461598 | F38: 4929 | K38: 88829865 | M38: 30947297 | P38: 46790600 | Q38: 2102560 | R38: 17485100 | Z38: 9506216 | AG38: 43698 | AH38: -35000000 | AI38: 휴먼→신한
A39: 5월 | B39: 161406094 | C39: 135818953 | D39: 25587141 | E39: 161134335 | F39: 1759 | G39: 270000 | K39: 100637725 | M39: 8884870 | P39: 4958100 | Q39: 3027550 | R39: 9000300 | Z39: 9310408 | AG39: 43763 | AH39: 3000000 | AI39: 우리
A40: 6월 | B40: 151007601 | C40: 158869719 | D40: -7862118 | E40: 150844249 | F40: 17620 | G40: 145732 | K40: 111871586 | M40: 13657380 | P40: 16649580 | Q40: 2849330 | R40: 5000000 | Z40: 8841843 | AG40: 43795 | AH40: -40614000 | AI40: 홍석민으로 출금
...

Sheet 거래처입금내역
B1: 2016년10월 | C1: 2016년11월 | D1: 2016년12월 | E1: 2017년1월 | F1: 2017년2월 | G1: 2017년3월 | H1: 2017년4월 | I1: 2017년5월 | J1: 2017년6월 | K1: 2017년7월 | L1: 2017년8월 | M1: 2017년9월 | N1: 2017년10월 | O1: 2017년11월 | P1: 2017년12월 | Q1: 2018년1월 | R1: 2018년2월 | S1: 2018년3월 | T1: 2018년4월 | U1: 2018년5월 | V1: 2018년6월 | W1: 2018년7월 | X1: 2018년8월 | Y1: 2018년9월 | Z1: 2018년10월 | AA1: 2018년11월 | AB1: 2018년12월 | AC1: 2019년1월 | AD1: 2019년2월 | AE1: 2019년3월 | AF1: 2019년4월 | AG1: 2019년5월 | AH1: 2019년6월 | AI1: 2019년7월 | AJ1: 2019년8월 | AK1: 2019년9월 | AL1: 2019년10월 | AM1: 2019년11월 | AN1: 2019년12월 | AO1: 2020년1월 | AP1: 2020년2월 | AQ1: 2020년3월 | AR1: 2020년4월 | AS1: 2020년5월 | AT1: 2020년6월 | AU1: 2020년7월 | AV1: 2020년8월 | AW1: 2020년9월 | AX1: 2020년10월 | AY1: 2020년11월 | AZ1: 2020년12월 | BA1: 2021년1월 | BB1: 2021년2월 | BC1: 2021년3월 | BD1: 2021년4월 | BE1: 2021년5월 | BF1: 2021년6월 | BG1: 2021년7월 | BH1: 2021년8월 | BI1: 2021년9월 | BJ1: 2021년10월 | BK1: 2021년11월 | BL1: 2021년12월 | BM1: 2022년01월 | BN1: 2022년02월 | BO1: 2022년03월 | BP1: 2022년04월 | BQ1: 2022년05월 | BR1: 2022년06월 | BS1: 2022년07월 | BT1: 2022년08월 | BU1: 2022년09월 | BV1: 2022년10월 | BW1: 2022년11월 | BX1: 2022년12월 | BY1: 2023년1월 | BZ1: 2023년2월 | CA1: 2023년3월 | CB1: 2023년4월 | CC1: 2023년5월 | CD1: 2023년6월 | CE1: 2023년7월 | CF1: 2023년8월 | CG1: 2023년9월 | CH1: 2023년10월 | CI1: 2023년11월 | CJ1: 2023년12월 | CK1: 2024년1월 | CL1: 2024년2월 | CM1: 2024년3월 | CN1: 2024년4월 | CO1: 2024년5월 | CP1: 2024년6월 | CQ1: 2024년7월 | CR1: 2024년8월 | CS1: 2024년9월 | CT1: 2024년10월 | CU1: 2024년11월 | CV1: 2024년12월 | CW1: 2025년1월 | CX1: 2025년2월 | CY1: 2025년3월 | CZ1: 2025년4월 | DA1: 2025년5월 | DB1: 2025년6월 | DC1: 2025년7월 | DD1: 2025년8월 | DE1: 2025년9월 | DF1: 2025년10월 | DG1: 2025년11월 | DH1: 2025년12월 | DI1: 2026년 1월 | DJ1: 2026년 2월 | DK1: 2026년 3월 | DL1: 2026년 4월 | DM1: 2026년 5월 | DN1: 2026년 6월 | DO1: 2026년 7월 | DP1: 2026년 8월 | DQ1: 2026년 9월 | DR1: 2026년 10월 | DS1: 2026년 11월 | DT1: 2026년 12월 | DV1: 2020년 합계 | DW1: 2021년 합계 | DX1: 2022년 합계 | DY1: 2023년 합계 | DZ1: 2024년 합계 | EA1: 2025년 합계 | EB1: 2026년 합계
A2: 하랑 | T2: 6460000 | DV2: =SUM(AO2:AZ2) -> 0 | DW2: =SUM(BA2:BL2) -> 0 | DX2: =SUM(BM2:BX2) -> 0 | DZ2: =SUM(CK2:CV2) -> 0 | EA2: =SUM(CW2:DH2) -> 0 | EB2: =SUM(DI2:DT2) -> 0 | ED2: =SUM(B2:DU2) -> 6460000
A3: 동우공영(주) | B3: 1056000 | E3: 2816000 | DV3: =SUM(AO3:AZ3) -> 0 | DW3: =SUM(BA3:BL3) -> 0 | DX3: =SUM(BM3:BX3) -> 0 | DY3: =SUM(BY3:CJ3) -> 0 | DZ3: =SUM(CK3:CV3) -> 0 | EA3: =SUM(CW3:DH3) -> 0 | EB3: =SUM(DI3:DT3) -> 0 | ED3: =SUM(B3:DU3) -> 3872000
A4: 디오라이트 | Q4: 374000 | DV4: =SUM(AO4:AZ4) -> 0 | DW4: =SUM(BA4:BL4) -> 0 | DX4: =SUM(BM4:BX4) -> 0 | DY4: =SUM(BY4:CJ4) -> 0 | DZ4: =SUM(CK4:CV4) -> 0 | EA4: =SUM(CW4:DH4) -> 0 | EB4: =SUM(DI4:DT4) -> 0 | ED4: =SUM(B4:DU4) -> 374000
A5: 이상신(라이트스톰) | M5: 1815000 | DV5: =SUM(AO5:AZ5) -> 0 | DW5: =SUM(BA5:BL5) -> 0 | DX5: =SUM(BM5:BX5) -> 0 | DY5: =SUM(BY5:CJ5) -> 0 | DZ5: =SUM(CK5:CV5) -> 0 | EA5: =SUM(CW5:DH5) -> 0 | EB5: =SUM(DI5:DT5) -> 0 | ED5: =SUM(B5:DU5) -> 1815000
A6: (주)삼익 | M6: 176000 | O6: 880000 | P6: 1056000 | Q6: 638000 | DV6: =SUM(AO6:AZ6) -> 0 | DW6: =SUM(BA6:BL6) -> 0 | DX6: =SUM(BM6:BX6) -> 0 | DY6: =SUM(BY6:CJ6) -> 0 | DZ6: =SUM(CK6:CV6) -> 0 | EA6: =SUM(CW6:DH6) -> 0 | EB6: =SUM(DI6:DT6) -> 0 | ED6: =SUM(B6:DU6) -> 2750000
A7: 김정용(샤인컴퍼니) | M7: 176000 | DV7: =SUM(AO7:AZ7) -> 0 | DW7: =SUM(BA7:BL7) -> 0 | DX7: =SUM(BM7:BX7) -> 0 | DY7: =SUM(BY7:CJ7) -> 0 | DZ7: =SUM(CK7:CV7) -> 0 | EA7: =SUM(CW7:DH7) -> 0 | EB7: =SUM(DI7:DT7) -> 0 | ED7: =SUM(B7:DU7) -> 176000
A8: 선앤문 | H8: 551100 | L8: 605000 | DV8: =SUM(AO8:AZ8) -> 0 | DW8: =SUM(BA8:BL8) -> 0 | DX8: =SUM(BM8:BX8) -> 0 | DY8: =SUM(BY8:CJ8) -> 0 | DZ8: =SUM(CK8:CV8) -> 0 | EA8: =SUM(CW8:DH8) -> 0 | EB8: =SUM(DI8:DT8) -> 0 | ED8: =SUM(B8:DU8) -> 1156100
A9: (주)씨앤에스자산관 | I9: 47740000 | J9: 12573000 | K9: 4752000 | L9: 12507000 | M9: 5940000 | N9: 6160000 | O9: 6600000 | P9: 26026000 | Q9: 75625000 | R9: 38722200 | S9: 968000 | DV9: =SUM(AO9:AZ9) -> 0 | DW9: =SUM(BA9:BL9) -> 0 | DX9: =SUM(BM9:BX9) -> 0 | DY9: =SUM(BY9:CJ9) -> 0 | DZ9: =SUM(CK9:CV9) -> 0 | EA9: =SUM(CW9:DH9) -> 0 | EB9: =SUM(DI9:DT9) -> 0 | ED9: =SUM(B9:DU9) -> 237613200
A10: 씨제이이앤엠주식회 | M10: 8470000 | DV10: =SUM(AO10:AZ10) -> 0 | DW10: =SUM(BA10:BL10) -> 0 | DX10: =SUM(BM10:BX10) -> 0 | DY10: =SUM(BY10:CJ10) -> 0 | DZ10: =SUM(CK10:CV10) -> 0 | EA10: =SUM(CW10:DH10) -> 0 | EB10: =SUM(DI10:DT10) -> 0 | ED10: =SUM(B10:DU10) -> 8470000
A11: (주)알앤지서비스 | M11: 3047000 | N11: 968000 | O11: 88000 | DV11: =SUM(AO11:AZ11) -> 0 | DW11: =SUM(BA11:BL11) -> 0 | DX11: =SUM(BM11:BX11) -> 0 | DY11: =SUM(BY11:CJ11) -> 0 | DZ11: =SUM(CK11:CV11) -> 0 | EA11: =SUM(CW11:DH11) -> 0 | EB11: =SUM(DI11:DT11) -> 0 | ED11: =SUM(B11:DU11) -> 4103000
A12: 이영찬(레이허) | E12: 1727000 | DV12: =SUM(AO12:AZ12) -> 0 | DW12: =SUM(BA12:BL12) -> 0 | DX12: =SUM(BM12:BX12) -> 0 | DY12: =SUM(BY12:CJ12) -> 0 | DZ12: =SUM(CK12:CV12) -> 0 | EA12: =SUM(CW12:DH12) -> 0 | EB12: =SUM(DI12:DT12) -> 0 | ED12: =SUM(B12:DU12) -> 1727000
A13: 최인경(밈포인 | B13: 715000 | C13: 929500 | D13: 731500 | E13: 495000 | G13: 962500 | H13: 253000 | DV13: =SUM(AO13:AZ13) -> 0 | DW13: =SUM(BA13:BL13) -> 0 | DX13: =SUM(BM13:BX13) -> 0 | DY13: =SUM(BY13:CJ13) -> 0 | DZ13: =SUM(CK13:CV13) -> 0 | EA13: =SUM(CW13:DH13) -> 0 | EB13: =SUM(DI13:DT13) -> 0 | ED13: =SUM(B13:DU13) -> 4086500
A14: 조동석(열린, 썬앤문) | E14: 6167030 | DV14: =SUM(AO14:AZ14) -> 0 | DW14: =SUM(BA14:BL14) -> 0 | DX14: =SUM(BM14:BX14) -> 0 | DY14: =SUM(BY14:CJ14) -> 0 | DZ14: =SUM(CK14:CV14) -> 0 | EA14: =SUM(CW14:DH14) -> 0 | EB14: =SUM(DI14:DT14) -> 0 | ED14: =SUM(B14:DU14) -> 6167030
A15: 파이널스페셜인펙트 | C15: 363000 | E15: 396000 | I15: 418000 | K15: 154000 | Q15: 154000 | CO15: 374000 | CS15: 572000 | DV15: =SUM(AO15:AZ15) -> 0 | DW15: =SUM(BA15:BL15) -> 0 | DX15: =SUM(BM15:BX15) -> 0 | DY15: =SUM(BY15:CJ15) -> 0 | DZ15: =SUM(CK15:CV15) -> 946000 | EA15: =SUM(CW15:DH15) -> 0 | EB15: =SUM(DI15:DT15) -> 0 | ED15: =SUM(B15:DU15) -> 2431000
A16: 파이로특수기획(우길택) | L16: 495000 | DV16: =SUM(AO16:AZ16) -> 0 | DW16: =SUM(BA16:BL16) -> 0 | DX16: =SUM(BM16:BX16) -> 0 | DY16: =SUM(BY16:CJ16) -> 0 | DZ16: =SUM(CK16:CV16) -> 0 | EA16: =SUM(CW16:DH16) -> 0 | EB16: =SUM(DI16:DT16) -> 0 | ED16: =SUM(B16:DU16) -> 495000
A17: 한국교육방송공 | W17: 1683000 | DV17: =SUM(AO17:AZ17) -> 0 | DW17: =SUM(BA17:BL17) -> 0 | DX17: =SUM(BM17:BX17) -> 0 | DY17: =SUM(BY17:CJ17) -> 0 | DZ17: =SUM(CK17:CV17) -> 0 | EA17: =SUM(CW17:DH17) -> 0 | EB17: =SUM(DI17:DT17) -> 0 | ED17: =SUM(B17:DU17) -> 1683000
A18: (주)만석푸드패 | U18: 5076500 | V18: 3113000 | W18: 3113000 | X18: 3356793 | DV18: =SUM(AO18:AZ18) -> 0 | DW18: =SUM(BA18:BL18) -> 0 | DX18: =SUM(BM18:BX18) -> 0 | DY18: =SUM(BY18:CJ18) -> 0 | DZ18: =SUM(CK18:CV18) -> 0 | EA18: =SUM(CW18:DH18) -> 0 | EB18: =SUM(DI18:DT18) -> 0 | ED18: =SUM(B18:DU18) -> 14659293
A19: 하나아트 | Y19: 180000 | DV19: =SUM(AO19:AZ19) -> 0 | DW19: =SUM(BA19:BL19) -> 0 | DX19: =SUM(BM19:BX19) -> 0 | DY19: =SUM(BY19:CJ19) -> 0 | DZ19: =SUM(CK19:CV19) -> 0 | EA19: =SUM(CW19:DH19) -> 0 | EB19: =SUM(DI19:DT19) -> 0 | ED19: =SUM(B19:DU19) -> 180000
A20: (주)인터비즈시 | Y20: 5434000 | DV20: =SUM(AO20:AZ20) -> 0 | DW20: =SUM(BA20:BL20) -> 0 | DX20: =SUM(BM20:BX20) -> 0 | DY20: =SUM(BY20:CJ20) -> 0 | DZ20: =SUM(CK20:CV20) -> 0 | EA20: =SUM(CW20:DH20) -> 0 | EB20: =SUM(DI20:DT20) -> 0 | ED20: =SUM(B20:DU20) -> 5434000
A21: (주)잡플러스 | R21: 6864000 | S21: 616000 | T21: 1320000 | U21: 352000 | X21: 440000 | Y21: 3019500 | DV21: =SUM(AO21:AZ21) -> 0 | DW21: =SUM(BA21:BL21) -> 0 | DX21: =SUM(BM21:BX21) -> 0 | DY21: =SUM(BY21:CJ21) -> 0 | DZ21: =SUM(CK21:CV21) -> 0 | EA21: =SUM(CW21:DH21) -> 0 | EB21: =SUM(DI21:DT21) -> 0 | ED21: =SUM(B21:DU21) -> 12611500
A22: (주)열린 | I22: 734800 | P22: 3969020 | R22: 902000 | T22: 913000 | U22: 2543640 | W22: 1914000 | Z22: 484000 | DV22: =SUM(AO22:AZ22) -> 0 | DW22: =SUM(BA22:BL22) -> 0 | DX22: =SUM(BM22:BX22) -> 0 | DY22: =SUM(BY22:CJ22) -> 0 | DZ22: =SUM(CK22:CV22) -> 0 | EA22: =SUM(CW22:DH22) -> 0 | EB22: =SUM(DI22:DT22) -> 0 | ED22: =SUM(B22:DU22) -> 11460460
A23: (주)영우트러스 | B23: 1500000 | C23: 2000000 | D23: 2000000 | E23: 1500000 | F23: 1833000 | H23: 1380500 | J23: 1006500 | K23: 2000000 | M23: 3071000 | P23: 2000000 | R23: 2207500 | U23: 385000 | X23: 319000 | AA23: 110000 | AB23: 387200 | DV23: =SUM(AO23:AZ23) -> 0 | DW23: =SUM(BA23:BL23) -> 0 | DX23: =SUM(BM23:BX23) -> 0 | DY23: =SUM(BY23:CJ23) -> 0 | DZ23: =SUM(CK23:CV23) -> 0 | EA23: =SUM(CW23:DH23) -> 0 | EB23: =SUM(DI23:DT23) -> 0 | ED23: =SUM(B23:DU23) -> 21699700
A24: 신호준(더막스) | AC24: 1221000 | DV24: =SUM(AO24:AZ24) -> 0 | DW24: =SUM(BA24:BL24) -> 0 | DX24: =SUM(BM24:BX24) -> 0 | DY24: =SUM(BY24:CJ24) -> 0 | DZ24: =SUM(CK24:CV24) -> 0 | EA24: =SUM(CW24:DH24) -> 0 | EB24: =SUM(DI24:DT24) -> 0 | ED24: =SUM(B24:DU24) -> 1221000
A25: (주)안성렌탈 | K25: 1919500 | L25: 517000 | M25: 16601750 | N25: 3564000 | O25: 4202000 | P25: 15790500 | AC25: 3195500 | DV25: =SUM(AO25:AZ25) -> 0 | DW25: =SUM(BA25:BL25) -> 0 | DX25: =SUM(BM25:BX25) -> 0 | DY25: =SUM(BY25:CJ25) -> 0 | DZ25: =SUM(CK25:CV25) -> 0 | EA25: =SUM(CW25:DH25) -> 0 | EB25: =SUM(DI25:DT25) -> 0 | ED25: =SUM(B25:DU25) -> 45790250
A26: (주)후니드 | B26: 1936000 | C26: 440000 | D26: 352000 | E26: 2212100 | F26: 1670350 | G26: 880000 | H26: 616000 | I26: 1771000 | J26: 2992000 | K26: 440000 | L26: 2145000 | M26: 4752000 | N26: 4103000 | O26: 4840000 | P26: 2904000 | Q26: 2420000 | V26: 778800 | W26: 154000 | Y26: 2376000 | AA26: 6996000 | AB26: 10714000 | AC26: 12551000 | DV26: =SUM(AO26:AZ26) -> 0 | DW26: =SUM(BA26:BL26) -> 0 | DX26: =SUM(BM26:BX26) -> 0 | DY26: =SUM(BY26:CJ26) -> 0 | DZ26: =SUM(CK26:CV26) -> 0 | EA26: =SUM(CW26:DH26) -> 0 | EB26: =SUM(DI26:DT26) -> 0 | ED26: =SUM(B26:DU26) -> 68043250
A27: (주)한국에이브이 | AA27: 726000 | AF27: 385000 | DV27: =SUM(AO27:AZ27) -> 0 | DW27: =SUM(BA27:BL27) -> 0 | DX27: =SUM(BM27:BX27) -> 0 | DY27: =SUM(BY27:CJ27) -> 0 | DZ27: =SUM(CK27:CV27) -> 0 | EA27: =SUM(CW27:DH27) -> 0 | EB27: =SUM(DI27:DT27) -> 0 | ED27: =SUM(B27:DU27) -> 1111000
A28: 김수현(나비특 | C28: 1826000 | E28: 4257000 | H28: 209000 | K28: 2222000 | M28: 2926000 | P28: 2937000 | S28: 2277000 | U28: 726000 | X28: 1716000 | AF28: 2673000 | DV28: =SUM(AO28:AZ28) -> 0 | DW28: =SUM(BA28:BL28) -> 0 | DX28: =SUM(BM28:BX28) -> 0 | DY28: =SUM(BY28:CJ28) -> 0 | DZ28: =SUM(CK28:CV28) -> 0 | EA28: =SUM(CW28:DH28) -> 0 | EB28: =SUM(DI28:DT28) -> 0 | ED28: =SUM(B28:DU28) -> 21769000
A29: (주)한성엠에스 | B29: 20148700 | C29: 33132880 | D29: 16562040 | E29: 23259500 | F29: 23590930 | G29: 24308724 | H29: 16030575 | I29: 22629354 | J29: 16329434 | K29: 19975197 | L29: 25484558 | M29: 31043430 | N29: 34257102 | O29: 43951117 | P29: 44539080 | Q29: 39859622 | R29: 24308394 | S29: 34753950 | T29: 6512000 | U29: 75843968 | V29: 23311200 | W29: 42374200 | X29: 69179000 | Y29: 36865730 | Z29: 81372830 | AA29: 50114240 | AB29: 48826140 | AC29: 43039700 | AD29: 4922500 | AE29: 1463000 | AF29: 209000 | DV29: =SUM(AO29:AZ29) -> 0 | DW29: =SUM(BA29:BL29) -> 0 | DX29: =SUM(BM29:BX29) -> 0 | DY29: =SUM(BY29:CJ29) -> 0 | DZ29: =SUM(CK29:CV29) -> 0 | EA29: =SUM(CW29:DH29) -> 0 | EB29: =SUM(DI29:DT29) -> 0 | ED29: =SUM(B29:DU29) -> 978198095
A30: 라이트스케치 | X30: 396000 | AB30: 869000 | AD30: 1023000 | AG30: 154000 | DV30: =SUM(AO30:AZ30) -> 0 | DW30: =SUM(BA30:BL30) -> 0 | DX30: =SUM(BM30:BX30) -> 0 | DY30: =SUM(BY30:CJ30) -> 0 | DZ30: =SUM(CK30:CV30) -> 0 | EA30: =SUM(CW30:DH30) -> 0 | EB30: =SUM(DI30:DT30) -> 0 | ED30: =SUM(B30:DU30) -> 2442000
A31: (주)나우글로벌 | AG31: 3829000 | DV31: =SUM(AO31:AZ31) -> 0 | DW31: =SUM(BA31:BL31) -> 0 | DX31: =SUM(BM31:BX31) -> 0 | DY31: =SUM(BY31:CJ31) -> 0 | DZ31: =SUM(CK31:CV31) -> 0 | EA31: =SUM(CW31:DH31) -> 0 | EB31: =SUM(DI31:DT31) -> 0 | ED31: =SUM(B31:DU31) -> 3829000
A32: (주)아트빈 | J32: 270000 | Q32: 1551000 | V32: 2244000 | Z32: 3000000 | AH32: 1083506 | DV32: =SUM(AO32:AZ32) -> 0 | DW32: =SUM(BA32:BL32) -> 0 | DX32: =SUM(BM32:BX32) -> 0 | DY32: =SUM(BY32:CJ32) -> 0 | DZ32: =SUM(CK32:CV32) -> 0 | EA32: =SUM(CW32:DH32) -> 0 | EB32: =SUM(DI32:DT32) -> 0 | ED32: =SUM(B32:DU32) -> 8148506
A33: (주)엠씨피인터네셔 | Y33: 874500 | AA33: 440000 | AC33: 1100000 | AI33: 77000 | DV33: =SUM(AO33:AZ33) -> 0 | DW33: =SUM(BA33:BL33) -> 0 | DX33: =SUM(BM33:BX33) -> 0 | DY33: =SUM(BY33:CJ33) -> 0 | DZ33: =SUM(CK33:CV33) -> 0 | EA33: =SUM(CW33:DH33) -> 0 | EB33: =SUM(DI33:DT33) -> 0 | ED33: =SUM(B33:DU33) -> 2491500
A34: 이용대(강원기업) | M34: 462000 | AG34: 671000 | AH34: 748000 | AI34: 330000 | AJ34: 330000 | DV34: =SUM(AO34:AZ34) -> 0 | DW34: =SUM(BA34:BL34) -> 0 | DX34: =SUM(BM34:BX34) -> 0 | DY34: =SUM(BY34:CJ34) -> 0 | DZ34: =SUM(CK34:CV34) -> 0 | EA34: =SUM(CW34:DH34) -> 0 | EB34: =SUM(DI34:DT34) -> 0 | ED34: =SUM(B34:DU34) -> 2541000
A35: 스파이더(리깅) | K35: 1928300 | N35: 1397000 | O35: 1267000 | P35: 1023000 | S35: 2500000 | T35: 3115500 | U35: 1155000 | V35: 3866500 | W35: 621500 | AA35: 583000 | AC35: 1474000 | AD35: 418000 | AK35: 92400 | DV35: =SUM(AO35:AZ35) -> 0 | DW35: =SUM(BA35:BL35) -> 0 | DX35: =SUM(BM35:BX35) -> 0 | DY35: =SUM(BY35:CJ35) -> 0 | DZ35: =SUM(CK35:CV35) -> 0 | EA35: =SUM(CW35:DH35) -> 0 | EB35: =SUM(DI35:DT35) -> 0 | ED35: =SUM(B35:DU35) -> 19441200
A36: (주)프레임컴퍼 | B36: 3366000 | C36: 1760000 | D36: 2079000 | E36: 5791500 | G36: 594000 | H36: 6985000 | J36: 3223000 | K36: 3927000 | L36: 2024000 | M36: 4026000 | N36: 594000 | AI36: 176000 | AK36: 704000 | DV36: =SUM(AO36:AZ36) -> 0 | DW36: =SUM(BA36:BL36) -> 0 | DX36: =SUM(BM36:BX36) -> 0 | DY36: =SUM(BY36:CJ36) -> 0 | DZ36: =SUM(CK36:CV36) -> 0 | EA36: =SUM(CW36:DH36) -> 0 | EB36: =SUM(DI36:DT36) -> 0 | ED36: =SUM(B36:DU36) -> 35249500
A37: 쇼매이드 | AC37: 286000 | AK37: 198000 | AM37: 451000 | DV37: =SUM(AO37:AZ37) -> 0 | DW37: =SUM(BA37:BL37) -> 0 | DX37: =SUM(BM37:BX37) -> 0 | DY37: =SUM(BY37:CJ37) -> 0 | DZ37: =SUM(CK37:CV37) -> 0 | EA37: =SUM(CW37:DH37) -> 0 | EB37: =SUM(DI37:DT37) -> 0 | ED37: =SUM(B37:DU37) -> 935000
A38: 식품안전정보원 | AD38: 1760000 | AN38: 1760000 | DV38: =SUM(AO38:AZ38) -> 0 | DW38: =SUM(BA38:BL38) -> 0 | DX38: =SUM(BM38:BX38) -> 0 | DY38: =SUM(BY38:CJ38) -> 0 | DZ38: =SUM(CK38:CV38) -> 0 | EA38: =SUM(CW38:DH38) -> 0 | EB38: =SUM(DI38:DT38) -> 0 | ED38: =SUM(B38:DU38) -> 3520000
A39: 가오프로젝트 | H39: 32599600 | M39: 23347500 | Z39: 3388000 | AB39: 3960000 | AE39: 3520000 | AK39: 539000 | AN39: 42900000 | DV39: =SUM(AO39:AZ39) -> 0 | DW39: =SUM(BA39:BL39) -> 0 | DX39: =SUM(BM39:BX39) -> 0 | DY39: =SUM(BY39:CJ39) -> 0 | DZ39: =SUM(CK39:CV39) -> 0 | EA39: =SUM(CW39:DH39) -> 0 | EB39: =SUM(DI39:DT39) -> 0 | ED39: =SUM(B39:DU39) -> 110254100
A40: (주)라이팅코리아->라이팅코리아프로 | B40: 308000 | O40: 660000 | U40: 572000 | Z40: 748000 | AA40: 1760000 | AC40: 1650000 | AG40: 660000 | AH40: 1331000 | AK40: 308000 | AM40: 1683000 | AN40: 704000 | BX40: 1100000 | BY40: 10626000 | BZ40: 550000 | CB40: 2376000 | CC40: 6171000 | CE40: 1232000 | CF40: 3113000 | CH40: 1001000 | CI40: 1188000 | CR40: 1210000 | CS40: 429000 | CV40: 715000 | DV40: =SUM(AO40:AZ40) -> 0 | DW40: =SUM(BA40:BL40) -> 0 | DX40: =SUM(BM40:BX40) -> 1100000 | DY40: =SUM(BY40:CJ40) -> 26257000 | DZ40: =SUM(CK40:CV40) -> 2354000 | EA40: =SUM(CW40:DH40) -> 0 | EB40: =SUM(DI40:DT40) -> 0 | ED40: =SUM(B40:DU40) -> 40095000
...

Sheet 주차
A1: 구분 | B1: 6월 | C1: 주차비 | D1: 공급가액 | E1: 부가세 | F1: 카드 수수료 | G1: 통장입금액
A2: 파주 | B2: 금촌 | C2: 4126100 | D2: 3959117 | E2: 186127 | F2: 36837 | G2: 4089263
B3: 문산 | C3: 4333575 | D3: 4228439 | E3: 114681 | F3: 22791 | G3: 4310784
B4: 법원사거리 | C4: 3412475 | D4: 3285739 | E4: 175193 | F4: 27091 | G4: 3385384
A5: 용인 | B5: 다보스병원 | C5: 9927930 | D5: 9034488 | E5: 896169 | F5: 196081 | G5: 9731849
A6: 계 | C6: =SUM(C2:C5) -> 21800080 | D6: =SUM(D2:D5) -> 20507783 | E6: =SUM(E2:E5) -> 1372170 | F6: =SUM(F2:F5) -> 282800 | G6: =SUM(G2:G5) -> 21517280
A7: 구분 | B7: 7월 | C7: 주차비 | D7: 공급가액 | E7: 부가세 | F7: 카드 수수료 | G7: 통장입금액
A8: 파주 | B8: 금촌 | C8: 5014660 | D8: 4786925 | E8: 227735 | F8: 49081 | G8: 4965579
B9: 문산 | C9: 5574770 | D9: 5450655 | E9: 140023 | F9: 28943 | G9: 5545827
B10: 법원사거리 | C10: 3728975 | D10: 3610580 | E10: 187552 | F10: 23963 | G10: 3705012
A11: 용인 | B11: 다보스병원 | C11: 12775200 | D11: 11704129 | E11: 1075616 | F11: 237094 | G11: 12588106
A12: 계 | C12: =SUM(C8:C11) -> 27093605 | D12: =SUM(D8:D11) -> 25552289 | E12: =SUM(E8:E11) -> 1630926 | F12: =SUM(F8:F11) -> 339081 | G12: =SUM(G8:G11) -> 26804524
A13: 구분 | B13: 8월 | C13: 주차비 | D13: 공급가액 | E13: 부가세 | F13: 카드 수수료 | G13: 통장입금액
A14: 파주 | B14: 금촌 | C14: 4177600 | D14: 4007509 | E14: 170091 | F14: 36791 | G14: 4140840
B15: 문산 | C15: 3974845 | D15: 3925090 | E15: 56118 | F15: 11152 | G15: 3963693
B16: 법원사거리 | C16: 3160775 | D16: 3058793 | E16: 143977 | F16: 21178 | G16: 3139597
A17: 용인 | B17: 다보스병원 | C17: 12420300 | D17: 11333264 | E17: 1088854 | F17: 237274 | G17: 12183026
A18: 계 | C18: =SUM(C14:C17) -> 23733520 | D18: =SUM(D14:D17) -> 22324656 | E18: =SUM(E14:E17) -> 1459040 | F18: =SUM(F14:F17) -> 306395 | G18: =SUM(G14:G17) -> 23427156
A19: 구분 | B19: 9월 | C19: 주차비 | D19: 공급가액 | E19: 부가세 | F19: 카드 수수료 | G19: 통장입금액
A20: 파주 | B20: 금촌 | C20: 4340450 | D20: 4167329 | E20: 173193 | F20: 37062 | G20: 4303388
B21: 문산 | C21: 4900250 | D21: 4747223 | E21: 159490 | F21: 36020 | G21: 4864230
B22: 법원사거리 | C22: 2930450 | D22: 2845611 | E22: 128769 | F22: 17218 | G22: 2913232
A23: 용인 | B23: 다보스병원 | C23: 14713500 | D23: 13605235 | E23: 1115537 | F23: 242475 | G23: 14471025
A24: 계 | C24: =SUM(C20:C23) -> 26884650 | D24: =SUM(D20:D23) -> 25365398 | E24: =SUM(E20:E23) -> 1576989 | F24: =SUM(F20:F23) -> 332775 | G24: =SUM(G20:G23) -> 26551875
A25: 구분 | B25: 10월 | C25: 주차비 | D25: 공급가액 | E25: 부가세 | F25: 카드 수수료 | G25: 통장입금액
A26: 파주 | B26: 금촌 | C26: 3898300 | D26: 3721300 | E26: 177236 | F26: 34595 | G26: 3863705
B27: 문산 | C27: 4285650 | D27: 4167178 | E27: 137633 | F27: 27986 | G27: 4257664
B28: 법원사거리 | C28: 2416200 | D28: 2332512 | E28: 120357 | F28: 17056 | G28: 2399144
A29: 용인 | B29: 다보스병원 | C29: 11900400 | D29: 10860525 | E29: 1050964 | F29: 228741 | G29: 11671659
A30: 계 | C30: =SUM(C26:C29) -> 22500550 | D30: =SUM(D26:D29) -> 21081515 | E30: =SUM(E26:E29) -> 1486190 | F30: =SUM(F26:F29) -> 308378 | G30: =SUM(G26:G29) -> 22192172
A31: 구분 | B31: 11월 | C31: 주차비 | D31: 공급가액 | E31: 부가세 | F31: 카드 수수료 | G31: 통장입금액
A32: 파주 | B32: 금촌 | C32: 3065725 | D32: 2951148 | E32: 114577 | F32: 24520 | G32: 3041205
B33: 문산 | C33: 4118800 | D33: 3996346 | E33: 128817 | F33: 27698 | G33: 4091102
B34: 법원사거리 | C34: 2546315 | D34: 2462869 | E34: 120495 | F34: 16677 | G34: 2529638
A35: 용인 | B35: 다보스병원 | C35: 13681900 | D35: 12719105 | E35: 964613 | F35: 216616 | G35: 13465284
A36: 계 | C36: =SUM(C32:C35) -> 23412740 | D36: =SUM(D32:D35) -> 22129468 | E36: =SUM(E32:E35) -> 1328502 | F36: =SUM(F32:F35) -> 285511 | G36: =SUM(G32:G35) -> 23127229
A37: 구분 | B37: 12월 | C37: 주차비 | D37: 공급가액 | E37: 부가세 | F37: 카드 수수료 | G37: 통장입금액
A38: 파주 | B38: 금촌 | C38: 3353940 | D38: 3208056 | E38: 145884 | F38: 31018 | G38: 3322922
B39: 문산 | C39: 3997700 | D39: 3861139 | E39: 136561 | F39: 30071 | G39: 3967629
B40: 법원사거리 | C40: 2547275 | D40: 2454759 | E40: 137829 | F40: 19620 | G40: 2527655
...

Sheet 2026년
A1: 날짜 | B1: 적요 | C1: 입금액(원) | D1: 출금액(원) | E1: 잔액(원) | F1: 계산서발행일 | G1: 계좌
A2: 전월이월 | E2: -56067066
A3: 46023 | B3: 파주 주차비 | C3: 42100 | E3: =E2+C3-D3 -> -56024966 | G3: 하나
A4: 46024 | B4: 다보스 주차비 | C4: 456982 | E4: =E3+C4-D4 -> -55567984 | G4: 하나
B5: 파주 주차비 | C5: 276346 | E5: =E4+C5-D5 -> -55291638 | G5: 하나
B6: 주식회사 쏘카 | C6: 440000 | E6: =E5+C6-D6 -> -54851638 | G6: 하나
B7: 국민윤희중-다보스 인건비 | D7: 241750 | E7: =E6+C7-D7 -> -55093388 | G7: 우리
B8: 농협한승철-다보스 인건비 | D8: 193400 | E8: =E7+C8-D8 -> -55286788 | G8: 우리
B9: 신한김동영-파주 인건비 | D9: 483500 | E9: =E8+C9-D9 -> -55770288 | G9: 우리
B10: 신한황태원(황태원)-다보스 생수 | D10: 28600 | E10: =E9+C10-D10 -> -55798888 | G10: 우리
B11: 농협한전(문산분회)-파주 전기요금 | D11: 122190 | E11: =E10+C11-D11 -> -55921078 | G11: 우리
B12: 농협이가영-금촌 식대 | D12: 37000 | E12: =E11+C12-D12 -> -55958078 | G12: 우리
A13: 46025 | B13: 파주 주차비 | C13: 1000 | E13: =E12+C13-D13 -> -55957078 | G13: 하나
A14: 46027 | B14: (주)삼구아이앤씨-소노벨 룸메이드 | C14: 34674420 | E14: =E13+C14-D14 -> -21282658 | F14: 46019 | G14: 우리
B15: 이경미 | D15: 26500000 | E15: =E14+C15-D15 -> -47782658 | G15: 우리
B16: 다보스 주차비 | C16: 413892 | E16: =E15+C16-D16 -> -47368766 | G16: 하나
B17: 파주 주차비 | C17: 128185 | E17: =E16+C17-D17 -> -47240581 | G17: 하나
A18: 46028 | B18: 다보스 주차비 | C18: 688049 | E18: =E17+C18-D18 -> -46552532 | G18: 하나
B19: 파주 주차비 | C19: 75791 | E19: =E18+C19-D19 -> -46476741 | G19: 하나
B20: 도봉（２１０） | D20: 6000000 | E20: =E19+C20-D20 -> -52476741 | F20: 부가가치세 납부 | G20: 기업
A21: 46029 | B21: 다보스 주차비 | C21: 1032797 | E21: =E20+C21-D21 -> -51443944 | G21: 하나
B22: 파주 주차비 | C22: 2164 | E22: =E21+C22-D22 -> -51441780 | G22: 하나
A23: 46030 | B23: 다보스 주차비 | C23: 361108 | E23: =E22+C23-D23 -> -51080672 | G23: 하나
B24: 75698007209642-00001 | D24: 748756 | E24: =E23+C24-D24 -> -51829428 | F24: 대출이자 | G24: 하나
A25: 46031 | B25: (주)삼구아이앤씨 | C25: 49743045 | E25: =E24+C25-D25 -> -2086383.3 | F25: 46026 | G25: 우리
B26: (주)삼구아이앤씨 | C26: 7353918 | E26: =E25+C26-D26 -> 5267534.7 | F26: 46026 | G26: 우리
B27: 주식회사 우림 | D27: 55816618 | E27: =E26+C27-D27 -> -50549083 | F27: 소노벨, 소노캄 | G27: 우리
B28: 토뱅최원희-다보스 인건비 | D28: 48350 | E28: =E27+C28-D28 -> -50597433 | G28: 우리
B29: 국민윤희중-다보스 인건비 | D29: 145050 | E29: =E28+C29-D29 -> -50742483 | G29: 우리
B30: 다보스 주차비 | C30: 355533 | E30: =E29+C30-D30 -> -50386950 | G30: 하나
B31: 조은커뮤니-H | D31: 38500 | E31: =E30+C31-D31 -> -50425450 | G31: 하나
B32: 이경미 | C32: 13000000 | E32: =E31+C32-D32 -> -37425450 | G32: 기업
A33: 46032 | B33: 12/21~말일 케이엠파크 미지급급여 | D33: 8246190 | E33: =E32+C33-D33 -> -45671640 | G33: 우리
B34: 소재덕? | D34: 91865 | E34: =E33+C34-D34 -> -45763505 | G34: 우리
B35: 완도급여(2명) | D35: 4168940 | E35: =E34+C35-D35 -> -49932445 | G35: 기업
B36: 박준식-경비수수료 | D36: 200000 | E36: =E35+C36-D36 -> -50132445 | G36: 기업
A37: 46034 | B37: 다보스 주차비 | C37: 397300 | E37: =E36+C37-D37 -> -49735145 | G37: 하나
B38: 신화에스피씨주식회사-김포현대 | C38: 8112500 | E38: =E37+C38-D38 -> -41622645 | F38: 46020 | G38: 기업
B39: (주)케이엠파크 | C39: 122627311 | E39: =E38+C39-D39 -> 81004666 | F39: 46022 | G39: 기업
B40: 임원급여(이경미) | D40: 4000000 | E40: =E39+C40-D40 -> 77004666 | G40: 기업
...

Sheet 2025년
