Workbook

Sheet 2026년 04월채움
A1: 2026년 04월 업체별 결산-외국인
A4: 도급 | B4: 상호 | C4: 지급액 | D4: 청구액 | E4: 차액 | F4: 결재 | G4: 입금 | H4: 미입금(세후)
A5: 두잉 | B5: 제주 | C5: =제주!N1 -> 0 | D5: =제주!P1 -> 0 | E5: =D5-C5 -> 0 | F5: 한달 | H5: =D5+(D5*10%)-G5 -> 0
A6: 삼구 | B6: 소노벨 | C6: =소노벨!O1 -> 58526840 | D6: =소노벨!Q1 -> 70429850 | E6: =D6-C6 -> 11903010 | F6: 매주 | G6: =23604295+27823510 -> 51427805 | H6: =D6+(D6*10%)-G6 -> 26045030
B7: 소노캄_기물 | C7: =소노캄_기물!O1 -> 12455000 | D7: =소노캄_기물!Q1 -> 14915000 | E7: =D7-C7 -> 2460000 | F7: 매주 | G7: 10381250 | H7: =D7+(D7*10%)-G7 -> 6025250
B8: 소노캄 | C8: =소노캄!N1 -> 37631740 | D8: =소노캄!P1 -> 46490140 | E8: =D8-C8 -> 8858400 | F8: 매주 | G8: 33338030 | H8: =D8+D9+((D8+D9)*10%)-G8 -> 22025124
B9: 소노캄_런드리 | C9: =소노캄_런드리!O3 -> 3200000 | D9: =소노캄_런드리!Q3 -> 3840000 | E9: =D9-C9 -> 640000 | F9: 매주
A10: ㈜프로에스콤 | B10: 포시 | C10: =포시!N1 -> 11131800 | D10: =포시!Q1 -> 12466800 | E10: =D10-C10 -> 1335000 | F10: 15/31 | G10: 13713480 | H10: =D10+(D10*10%)-G10 -> 0
B11: 시그니엘 | C11: =시그니엘!O1 -> 0 | D11: =시그니엘!R1 -> 0 | E11: =D11-C11 -> 0 | F11: 11/24 | H11: =D11+(D11*10%)-G11 -> 0
B12: 부산파크 | C12: =부산파크!O1 -> 350000 | D12: =부산파크!R1 -> 425000 | E12: =D12-C12 -> 75000 | F12: 15/31 | G12: 467500 | H12: =D12+(D12*10%)-G12 -> 0
A13: 호산서비스 | B13: 조선 | C13: =조선!O3 -> 1080000 | D13: =조선!R3 -> 1170000 | E13: =D13-C13 -> 90000 | F13: 15/31 | G13: 1287000 | H13: =D13+(D13*10%)-G13 -> 0
C14: =제주!O9 -> 0 | D14: =제주!Q9 -> 0 | E14: =D14-C14 -> 0
C15: =제주!O10 -> 0 | D15: =제주!Q10 -> 0 | E15: =D15-C15 -> 0
C16: =제주!O11 -> 0 | D16: =제주!Q11 -> 0 | E16: =D16-C16 -> 0
C17: =제주!O12 -> 0 | D17: =제주!Q12 -> 0 | E17: =D17-C17 -> 0
A18: 계 | C18: =SUM(C5:C17) -> 124375380 | D18: =SUM(D5:D17) -> 149736790 | E18: =SUM(E5:E17) -> 25361410 | G18: =SUM(G5:G17) -> 110615065 | H18: =SUM(H5:H17) -> 54095404
E19: =D19 -> 0

Sheet 제주
A1: 두잉-제주롯데호텔 | M1: 지급액 | N1: =SUM(K1:K9892) -> 0 | O1: 청구액 | P1: =SUM(L1:L9892) -> 0
A4: 날짜 | B4: 업체 | C4: 현장 | D4: 업무 | E4: 근무시간 | F4: 이름 | G4: 전화번호 | H4: 주민등록번호 | I4: 은행 | J4: 계좌번호 | K4: 지급액 | L4: 청구액

Sheet 조선
A1: 호산서비스-웨스턴 조선호텔
N3: 지급액 | O3: =SUM(K3:K9892) -> 1080000 | Q3: 청구액 | R3: =SUM(L3:L9892) -> 1170000
A4: 날짜 | B4: 업체 | C4: 현장 | D4: 업무 | E4: 근무시간 | F4: 이름 | G4: 총 근무일 | H4: 주민등록번호 | I4: 은행 | J4: 계좌번호 | K4: 지급액 | L4: 청구액
A5: 26.04.01~04.15 | B5: 호산서비스 | C5: 웨스틴 조선 서울 | D5: 룸메이드 | F5: 강미소 | G5: 4 | K5: =120000*G5 -> 480000 | L5: =130000*G5 -> 520000
A6: 26.04.01~04.15 | B6: 호산서비스 | C6: 웨스틴 조선 서울 | D6: 룸메이드 | F6: 김인정 | G6: 5 | K6: =120000*G6 -> 600000 | L6: =130000*G6 -> 650000

Sheet 소노벨
A1: 삼구-소노벨_룸메이드 | N1: 지급액 | O1: =SUM(K3:K9442) -> 58526840 | P1: 청구액 | Q1: =SUM(L3:L9442) -> 70429850 | R1: 이익금 | S1: =SUM(P1:P9442) -> 11903010
A4: 날짜 | B4: 업체 | C4: 현장 | D4: 업무 | E4: 근무시간 | F4: 이름 | G4: 전화번호 | H4: 주민등록번호 | I4: 은행 | J4: 계좌번호 | K4: 지급액 | L4: 청구액 | M4: 차감 | N4: 비고 | O4: 지급일 | P4: 차액
A5: 26.03.30~04.05 | B5: 삼구 | C5: 소노벨 | D5: 룸메이드 | F5: 할룽 | I5: 국민 | J5: 47940104348839 | K5: 550000 | L5: 650000 | O5: 4/10 지급 | P5: =L5-K5 -> 100000
A6: 26.03.30~04.05 | B6: 삼구 | C6: 소노벨 | D6: 룸메이드 | F6: 린 | I6: 하나 | J6: 35491018079107 | K6: 550000 | L6: 550000 | O6: 4/10 지급 | P6: =L6-K6 -> 0
A7: 26.03.30~04.05 | B7: 삼구 | C7: 소노벨 | D7: 룸메이드 | F7: 준호 | I7: 하나 | J7: 23391065673307 | K7: 536900 | L7: 636900 | O7: 4/10 지급 | P7: =L7-K7 -> 100000
A8: 26.03.30~04.05 | B8: 삼구 | C8: 소노벨 | D8: 룸메이드 | F8: 김보미 | I8: 하나 | J8: 23391065673307 | K8: 437500 | L8: 517500 | O8: 4/10 지급 | P8: =L8-K8 -> 80000
A9: 26.03.30~04.05 | B9: 삼구 | C9: 소노벨 | D9: 룸메이드 | F9: 조미나 | I9: 하나 | J9: 29991054312107 | K9: 427700 | L9: 527700 | O9: 4/10 지급 | P9: =L9-K9 -> 100000
A10: 26.03.30~04.05 | B10: 삼구 | C10: 소노벨 | D10: 룸메이드 | F10: 빔 | I10: 하나 | J10: 23391063977607 | K10: 424900 | L10: 524900 | O10: 4/10 지급 | P10: =L10-K10 -> 100000
A11: 26.03.30~04.05 | B11: 삼구 | C11: 소노벨 | D11: 룸메이드 | F11: 지혜 | I11: 하나 | J11: 23391049813107 | K11: 217000 | L11: 267000 | O11: 4/10 지급 | P11: =L11-K11 -> 50000
A12: 26.03.30~04.05 | B12: 삼구 | C12: 소노벨 | D12: 룸메이드 | F12: 미소 | I12: 농협 | J12: 3561594870383 | K12: 105000 | L12: 130000 | O12: 4/10 지급 | P12: =L12-K12 -> 25000
A13: 26.03.30~04.05 | B13: 삼구 | C13: 소노벨 | D13: 룸메이드 | F13: 수지라 | I13: 농협 | J13: 3561626523273 | K13: 210000 | L13: 260000 | O13: 4/10 지급 | P13: =L13-K13 -> 50000
A14: 26.03.30~04.05 | B14: 삼구 | C14: 소노벨 | D14: 룸메이드 | F14: 짠티마 | I14: 하나 | J14: 68091053420107 | K14: 210000 | L14: 260000 | O14: 4/10 지급 | P14: =L14-K14 -> 50000
A15: 26.03.30~04.05 | B15: 삼구 | C15: 소노벨 | D15: 룸메이드 | F15: 사라 | I15: 하나 | J15: 57191056846807 | K15: 536900 | L15: 636900 | O15: 4/10 지급 | P15: =L15-K15 -> 100000
A16: 26.03.30~04.05 | B16: 삼구 | C16: 소노벨 | D16: 룸메이드 | F16: 백 | I16: 하나 | J16: 39891066942107 | K16: 525000 | L16: 625000 | O16: 4/10 지급 | P16: =L16-K16 -> 100000
... A55: 26.04.06~04.12 | B55: 삼구 | C55: 소노벨 | D55: 룸메이드 | F55: 린 | I55: 하나 | J55: 35491018079107 | K55: 550000 | L55: 550000 | O55: 4/17 지급 | P55: =L55-K55 -> 0
A56: 26.04.06~04.12 | B56: 삼구 | C56: 소노벨 | D56: 룸메이드 | F56: 준호 | I56: 하나 | J56: 23391065673307 | K56: 604850 | L56: 753500 | M56: 28650 | N56: 3월 가스비 | O56: 4/17 지급 | P56: =L56-K56 -> 148650
A57: 26.04.06~04.12 | B57: 삼구 | C57: 소노벨 | D57: 룸메이드 | F57: 김보미 | I57: 하나 | J57: 23391065673307 | K57: 604850 | L57: 753500 | M57: 28650 | N57: 3월 가스비 | O57: 4/17 지급 | P57: =L57-K57 -> 148650
A58: 26.04.06~04.12 | B58: 삼구 | C58: 소노벨 | D58: 룸메이드 | F58: 조미나 | I58: 하나 | J58: 29991054312107 | K58: 318500 | L58: 393500 | O58: 4/17 지급 | P58: =L58-K58 -> 75000
A59: 26.04.06~04.12 | B59: 삼구 | C59: 소노벨 | D59: 룸메이드 | F59: 빔 | I59: 하나 | J59: 23391063977607 | K59: 315000 | L59: 390000 | O59: 4/17 지급 | P59: =L59-K59 -> 75000
A60: 26.04.06~04.12 | B60: 삼구 | C60: 소노벨 | D60: 룸메이드 | F60: 수지라 | I60: 농협 | J60: 3561626523273 | K60: 317100 | L60: 392100 | O60: 4/17 지급 | P60: =L60-K60 -> 75000
A61: 26.04.06~04.12 | B61: 삼구 | C61: 소노벨 | D61: 룸메이드 | F61: 짠티마 | I61: 하나 | J61: 68091053420107 | K61: 210000 | L61: 260000 | O61: 4/17 지급 | P61: =L61-K61 -> 50000
A62: 26.04.06~04.12 | B62: 삼구 | C62: 소노벨 | D62: 룸메이드 | F62: 사라 | I62: 하나 | J62: 57191056846807 | K62: 676420 | L62: 877100 | M62: 60680 | N62: 3월 가스비 | O62: 4/17 지급 | P62: =L62-K62 -> 200680
A63: 26.04.06~04.12 | B63: 삼구 | C63: 소노벨 | D63: 룸메이드 | F63: 백 | I63: 하나 | J63: 39891066942107 | K63: 642260 | L63: 875000 | M63: 92740 | N63: 3월 가스비 | O63: 4/17 지급 | P63: =L63-K63 -> 232740
A64: 26.04.06~04.12 | B64: 삼구 | C64: 소노벨 | D64: 룸메이드 | F64: 나비 | I64: 하나 | J64: 39891066942107 | K64: 642260 | L64: 875000 | M64: 92740 | N64: 3월 가스비 | O64: 4/17 지급 | P64: =L64-K64 -> 232740
A65: 26.04.06~04.12 | B65: 삼구 | C65: 소노벨 | D65: 룸메이드 | F65: 엘레나 | I65: 농협 | J65: 3560935626623 | K65: 420000 | L65: 520000 | O65: 4/17 지급 | P65: =L65-K65 -> 100000
A66: 26.04.06~04.12 | B66: 삼구 | C66: 소노벨 | D66: 룸메이드 | F66: 김하늘 | I66: 기업 | J66: 36110662801011 | K66: 527100 | L66: 652100 | O66: 4/17 지급 | P66: =L66-K66 -> 125000
A67: 26.04.06~04.12 | B67: 삼구 | C67: 소노벨 | D67: 룸메이드 | F67: 김수진 | I67: 농협 | J67: 3512536253663 | K67: 536900 | L67: 661900 | O67: 4/17 지급 | P67: =L67-K67 -> 125000
A68: 26.04.06~04.12 | B68: 삼구 | C68: 소노벨 | D68: 룸메이드 | F68: 김안나 | I68: 우리 | J68: 1002863255436 | K68: 541100 | L68: 666100 | O68: 4/17 지급 | P68: =L68-K68 -> 125000
A69: 26.04.06~04.12 | B69: 삼구 | C69: 소노벨 | D69: 룸메이드 | F69: 투 | I69: 국민 | J69: 48460104164408 | K69: 105000 | L69: 125000 | O69: 4/17 지급 | P69: =L69-K69 -> 20000
A70: 26.04.06~04.12 | B70: 삼구 | C70: 소노벨 | D70: 룸메이드 | F70: 로안 | I70: 국민 | J70: 48460104164862 | K70: 105000 | L70: 125000 | O70: 4/17 지급 | P70: =L70-K70 -> 20000
A71: 26.04.06~04.12 | B71: 삼구 | C71: 소노벨 | D71: 룸메이드 | F71: 황 | I71: 하나 | J71: 63591097804107 | K71: 107100 | L71: 127100 | O71: 4/17 지급 | P71: =L71-K71 -> 20000
A72: 26.04.06~04.12 | B72: 삼구 | C72: 소노벨 | D72: 룸메이드 | F72: 가은 | I72: 하나 | J72: 23391067991707 | K72: 548100 | L72: 648100 | O72: 4/17 지급 | P72: =L72-K72 -> 100000
A73: 26.04.06~04.12 | B73: 삼구 | C73: 소노벨 | D73: 룸메이드 | F73: 남(신) | I73: 전북 | J73: 9105205337638 | K73: 208500 | L73: 228500 | O73: 4/17 지급 | P73: =L73-K73 -> 20000
A74: 26.04.06~04.12 | B74: 삼구 | C74: 소노벨 | D74: 룸메이드 | F74: 푸(신) | I74: 전북 | J74: 9105205209318 | K74: 208500 | L74: 228500 | O74: 4/17 지급 | P74: =L74-K74 -> 20000
A75: 26.04.06~04.12 | B75: 삼구 | C75: 소노벨 | D75: 룸메이드 | F75: 북(신) | I75: 하나 | J75: 23391053112107 | K75: 105000 | L75: 125000 | O75: 4/17 지급 | P75: =L75-K75 -> 20000
A76: 26.04.06~04.12 | B76: 삼구 | C76: 소노벨 | D76: 룸메이드 | F76: 라징(신) | I76: 하나 | J76: 23391053112107 | K76: 105000 | L76: 125000 | O76: 4/17 지급 | P76: =L76-K76 -> 20000
... A86: 26.04.06~04.12 | B86: 삼구 | C86: 소노벨 | D86: 룸메이드 | F86: 아야 | I86: 전북 | J86: 9100050571420 | K86: 212100 | L86: 252100 | O86: 4/17 지급 | P86: =L86-K86 -> 40000
A87: 26.04.06~04.12 | B87: 삼구 | C87: 소노벨 | D87: 룸메이드 | F87: 아나르 | I87: 토스 | J87: 100178321014 | K87: 361810 | L87: 501400 | M87: 59590 | N87: 3월 가스비 (20만원 본사부담) | O87: 4/17 지급 | P87: =L87-K87 -> 139590
A88: 26.04.06~04.12 | B88: 삼구 | C88: 소노벨 | D88: 룸메이드 | F88: 소담 | I88: 제주 | J88: 50902008559049 | K88: 630000 | L88: 750000 | O88: 4/17 지급 | P88: =L88-K88 -> 120000
A89: 26.04.06~04.12 | B89: 삼구 | C89: 소노벨 | D89: 룸메이드 | F89: 아리오나 | I89: 우리 | J89: 1002044889759 | K89: 105000 | L89: 130000 | O89: 4/17 지급 | P89: =L89-K89 -> 25000
...

Sheet 소노캄_기물
A1: 삼구-소노캄_기물 | N1: 지급액 | O1: =SUM(K3:K9967) -> 12455000 | P1: 청구액 | Q1: =SUM(L3:L9967) -> 14915000 | R1: 차익금 | S1: =SUM(P5:P298) -> 2460000
A4: 날짜 | B4: 업체 | C4: 현장 | D4: 업무 | E4: 근무시간 | F4: 이름 | G4: 전화번호 | H4: 주민등록번호 | I4: 은행 | J4: 계좌번호 | K4: 지급액 | L4: 청구액 | M4: 차감 | N4: 비고 | O4: 지급일 | P4: 차액
A5: 46113 | B5: 삼구 | C5: 소노캄 고양(외국인) | D5: 기물 | F5: 김수빈 | G5: 010-9965-7441 | I5: 농협 | J5: 3522014792023 | K5: 100000 | L5: 120000 | O5: 4/10 지급 | P5: =L5-K5 -> 20000
A6: 46114 | B6: 삼구 | C6: 소노캄 고양(외국인) | D6: 기물 | F6: 김수빈 | G6: 010-9965-7441 | I6: 농협 | J6: 3522014792023 | K6: 100000 | L6: 120000 | O6: 4/10 지급 | P6: =L6-K6 -> 20000
A7: 46115 | B7: 삼구 | C7: 소노캄 고양(외국인) | D7: 기물 | F7: 김수빈 | G7: 010-9965-7441 | I7: 농협 | J7: 3522014792023 | K7: 100000 | L7: 120000 | O7: 4/10 지급 | P7: =L7-K7 -> 20000
A8: 46113 | B8: 삼구 | C8: 소노캄 고양(외국인) | D8: 기물 | F8: 김윤서 | G8: 010-8733-1338 | I8: 우리 | J8: 1002760342291 | K8: 100000 | L8: 120000 | O8: 4/10 지급 | P8: =L8-K8 -> 20000
A9: 46114 | B9: 삼구 | C9: 소노캄 고양(외국인) | D9: 기물 | F9: 김윤서 | G9: 010-8733-1338 | I9: 우리 | J9: 1002760342291 | K9: 100000 | L9: 120000 | O9: 4/10 지급 | P9: =L9-K9 -> 20000
A10: 46116 | B10: 삼구 | C10: 소노캄 고양(외국인) | D10: 기물 | F10: 김윤서 | G10: 010-8733-1338 | I10: 우리 | J10: 1002760342291 | K10: 100000 | L10: 120000 | O10: 4/10 지급 | P10: =L10-K10 -> 20000
A11: 46117 | B11: 삼구 | C11: 소노캄 고양(외국인) | D11: 기물 | F11: 김윤서 | G11: 010-8733-1338 | I11: 우리 | J11: 1002760342291 | K11: 100000 | L11: 120000 | O11: 4/10 지급 | P11: =L11-K11 -> 20000
A12: 46113 | B12: 삼구 | C12: 소노캄 고양(외국인) | D12: 기물 | F12: 아르오나(김아리) | G12: 010-9855-2211 | I12: 국민 | J12: 29250101395976 | K12: 100000 | L12: 120000 | O12: 4/10 지급 | P12: =L12-K12 -> 20000
A13: 46114 | B13: 삼구 | C13: 소노캄 고양(외국인) | D13: 기물 | F13: 아르오나(김아리) | G13: 010-9855-2211 | I13: 국민 | J13: 29250101395976 | K13: 100000 | L13: 120000 | O13: 4/10 지급 | P13: =L13-K13 -> 20000
A14: 46115 | B14: 삼구 | C14: 소노캄 고양(외국인) | D14: 기물 | F14: 아르오나(김아리) | G14: 010-9855-2211 | I14: 국민 | J14: 29250101395976 | K14: 100000 | L14: 120000 | O14: 4/10 지급 | P14: =L14-K14 -> 20000
A15: 46116 | B15: 삼구 | C15: 소노캄 고양(외국인) | D15: 기물 | F15: 아르오나(김아리) | G15: 010-9855-2211 | I15: 국민 | J15: 29250101395976 | K15: 100000 | L15: 120000 | O15: 4/10 지급 | P15: =L15-K15 -> 20000
A16: 46117 | B16: 삼구 | C16: 소노캄 고양(외국인) | D16: 기물 | F16: 아르오나(김아리) | G16: 010-9855-2211 | I16: 국민 | J16: 29250101395976 | K16: 100000 | L16: 120000 | O16: 4/10 지급 | P16: =L16-K16 -> 20000
A17: 46113 | B17: 삼구 | C17: 소노캄 고양(외국인) | D17: 기물 | F17: 더기(최다빈) | G17: 010-3254-5512 | I17: 전북 | J17: 9500020568373 | K17: 100000 | L17: 120000 | O17: 4/10 지급 | P17: =L17-K17 -> 20000
A18: 46116 | B18: 삼구 | C18: 소노캄 고양(외국인) | D18: 기물 | F18: 더기(최다빈) | G18: 010-3254-5512 | I18: 전북 | J18: 9500020568373 | K18: 100000 | L18: 120000 | O18: 4/10 지급 | P18: =L18-K18 -> 20000
A19: 46117 | B19: 삼구 | C19: 소노캄 고양(외국인) | D19: 기물 | F19: 더기(최다빈) | G19: 010-3254-5512 | I19: 전북 | J19: 9500020568373 | K19: 100000 | L19: 120000 | O19: 4/10 지급 | P19: =L19-K19 -> 20000
A20: 46114 | B20: 삼구 | C20: 소노캄 고양(외국인) | D20: 기물 | F20: 샤탈(김수연) | G20: 010-3665-4100 | I20: 국민 | J20: 29250101236893 | K20: 100000 | L20: 120000 | O20: 4/10 지급 | P20: =L20-K20 -> 20000
A21: 46116 | B21: 삼구 | C21: 소노캄 고양(외국인) | D21: 기물 | F21: 샤탈(김수연) | G21: 010-3665-4100 | I21: 국민 | J21: 29250101236893 | K21: 100000 | L21: 120000 | O21: 4/10 지급 | P21: =L21-K21 -> 20000
A22: 46117 | B22: 삼구 | C22: 소노캄 고양(외국인) | D22: 기물 | F22: 샤탈(김수연) | G22: 010-3665-4100 | I22: 국민 | J22: 29250101236893 | K22: 100000 | L22: 120000 | O22: 4/10 지급 | P22: =L22-K22 -> 20000
A23: 46116 | B23: 삼구 | C23: 소노캄 고양(외국인) | D23: 기물 | F23: 소시주(김연우) | G23: 010-4111-2357 | I23: 전북 | J23: 9100054122011 | K23: 100000 | L23: 120000 | O23: 4/10 지급 | P23: =L23-K23 -> 20000
... A28: 46117 | B28: 삼구 | C28: 소노캄 고양(외국인) | D28: 기물 | F28: 졸라(이다인) | G28: 010-8094-1903 | I28: 하나 | J28: 19891034404307 | K28: 100000 | L28: 120000 | O28: 4/10 지급 | P28: =L28-K28 -> 20000
A29: 46113 | B29: 삼구 | C29: 소노캄 고양(외국인) | D29: 기물 | F29: 투야 | I29: 하나 | J29: 19891034404307 | K29: 100000 | L29: 120000 | O29: 4/10 지급 | P29: =L29-K29 -> 20000
A30: 46114 | B30: 삼구 | C30: 소노캄 고양(외국인) | D30: 기물 | F30: 투야 | I30: 하나 | J30: 19891034404307 | K30: 100000 | L30: 120000 | O30: 4/10 지급 | P30: =L30-K30 -> 20000
A31: 46115 | B31: 삼구 | C31: 소노캄 고양(외국인) | D31: 기물 | F31: 투야 | I31: 하나 | J31: 19891034404307 | K31: 100000 | L31: 120000 | O31: 4/10 지급 | P31: =L31-K31 -> 20000
A32: 46116 | B32: 삼구 | C32: 소노캄 고양(외국인) | D32: 기물 | F32: 투야 | I32: 하나 | J32: 19891034404307 | K32: 100000 | L32: 120000 | O32: 4/10 지급 | P32: =L32-K32 -> 20000
A33: 46117 | B33: 삼구 | C33: 소노캄 고양(외국인) | D33: 기물 | F33: 투야 | I33: 하나 | J33: 19891034404307 | K33: 100000 | L33: 120000 | O33: 4/10 지급 | P33: =L33-K33 -> 20000
A34: 46116 | B34: 삼구 | C34: 소노캄 고양(외국인) | D34: 기물 | F34: 너모카 | I34: 토스 | J34: 100208736982 | K34: 100000 | L34: 120000 | O34: 4/10 지급 | P34: =L34-K34 -> 20000
A35: 46117 | B35: 삼구 | C35: 소노캄 고양(외국인) | D35: 기물 | F35: 너모카 | I35: 토스 | J35: 100208736982 | K35: 100000 | L35: 120000 | O35: 4/10 지급 | P35: =L35-K35 -> 20000
A36: 46113 | B36: 삼구 | C36: 소노캄 고양(외국인) | D36: 기물 | F36: 차키 | I36: 우리 | J36: 1002944606021 | K36: 100000 | L36: 120000 | O36: 4/10 지급 | P36: =L36-K36 -> 20000
A37: 46116 | B37: 삼구 | C37: 소노캄 고양(외국인) | D37: 기물 | F37: 차키 | I37: 우리 | J37: 1002944606021 | K37: 100000 | L37: 120000 | O37: 4/10 지급 | P37: =L37-K37 -> 20000
A38: 46117 | B38: 삼구 | C38: 소노캄 고양(외국인) | D38: 기물 | F38: 차키 | I38: 우리 | J38: 1002944606021 | K38: 100000 | L38: 120000 | O38: 4/10 지급 | P38: =L38-K38 -> 20000
A39: 46117 | B39: 삼구 | C39: 소노캄 고양(외국인) | D39: 기물 | F39: 김태리 | G39: 010-7788-1363 | I39: 전북 | J39: 9500021279810 | K39: 100000 | L39: 120000 | O39: 4/10 지급 | P39: =L39-K39 -> 20000
A40: 46118 | B40: 삼구 | C40: 소노캄 고양(외국인) | D40: 기물 | F40: 김수빈 | G40: 010-9965-7441 | I40: 농협 | J40: 3522014792023 | K40: 100000 | L40: 120000 | O40: 4/20 지급 | P40: =L40-K40 -> 20000
A41: 46119 | B41: 삼구 | C41: 소노캄 고양(외국인) | D41: 기물 | F41: 김수빈 | G41: 010-9965-7441 | I41: 농협 | J41: 3522014792023 | K41: 100000 | L41: 120000 | O41: 4/20 지급 | P41: =L41-K41 -> 20000
A42: 46120 | B42: 삼구 | C42: 소노캄 고양(외국인) | D42: 기물 | F42: 김수빈 | G42: 010-9965-7441 | I42: 농협 | J42: 3522014792023 | K42: 100000 | L42: 120000 | O42: 4/20 지급 | P42: =L42-K42 -> 20000
A43: 46121 | B43: 삼구 | C43: 소노캄 고양(외국인) | D43: 기물 | F43: 김수빈 | G43: 010-9965-7441 | I43: 농협 | J43: 3522014792023 | K43: 100000 | L43: 120000 | O43: 4/20 지급 | P43: =L43-K43 -> 20000
A44: 46122 | B44: 삼구 | C44: 소노캄 고양(외국인) | D44: 기물 | F44: 김수빈 | G44: 010-9965-7441 | I44: 농협 | J44: 3522014792023 | K44: 100000 | L44: 120000 | O44: 4/20 지급 | P44: =L44-K44 -> 20000
A45: 46118 | B45: 삼구 | C45: 소노캄 고양(외국인) | D45: 기물 | F45: 김윤서 | G45: 010-8733-1338 | I45: 우리 | J45: 1002760342291 | K45: 100000 | L45: 120000 | O45: 4/20 지급 | P45: =L45-K45 -> 20000
A46: 46119 | B46: 삼구 | C46: 소노캄 고양(외국인) | D46: 기물 | F46: 김윤서 | G46: 010-8733-1338 | I46: 우리 | J46: 1002760342291 | K46: 100000 | L46: 120000 | O46: 4/20 지급 | P46: =L46-K46 -> 20000
...

Sheet 소노캄
A1: 삼구-소노캄_룸메이드 | M1: 지급액 | N1: =SUM(K3:K9934) -> 37631740 | O1: 청구액 | P1: =SUM(L3:L9934) -> 46490140
A4: 날짜 | B4: 업체 | C4: 현장 | D4: 업무 | E4: 근무시간 | F4: 이름 | G4: 14유닛 이상 | H4: 주민번호 | I4: 은행 | J4: 계좌번호 | K4: 지급액 | L4: 청구액 | M4: 14유닛 이상(미반영)
A5: 26.04.01~04.05 | B5: 소노캄 | C5: 룸메이드 | F5: 이하나 | G5: 5 | K5: =M5-(G5*6200) -> 588040 | L5: 719040 | M5: 619040 | N5: =P12 -> SUMPRODUCT(--ISNUMBER(E6:K6), --(E6:K6>12), (E6:K6-12)*(E6:K6<13) + (E6:K6>=13)) | P5: 소노캄 룸메이드
A6: 26.04.01~04.05 | B6: 소노캄 | C6: 룸메이드 | F6: 이기숙 | G6: 5 | K6: =M6-(G6*6200) -> 609740 | L6: 740740 | M6: 640740 | P6: 근무일 25.01.05 ~
A7: 26.04.01~04.05 | B7: 소노캄 | C7: 룸메이드 | F7: 이나영 | G7: 4 | K7: =M7-(G7*6200) -> 488660 | L7: 593460 | M7: 513460 | P7: *청구 12만원
A8: 26.04.01~04.05 | B8: 소노캄 | C8: 룸메이드 | F8: 김유나 | G8: 3 | K8: =M8-(G8*6200) -> 473780 | L8: 572380 | M8: 492380 | P8: *지급 10만원
A9: 26.04.01~04.05 | B9: 소노캄 | C9: 룸메이드 | F9: 처머 | G9: 1 | K9: =M9-(G9*6200) -> 101240 | L9: 127440 | M9: 107440 | P9: *13유닛부터 +1유닛(6,200원) 자체 수익
A10: 26.04.01~04.05 | B10: 소노캄 | C10: 룸메이드 | F10: 임아리 | G10: 5 | K10: =M10-(G10*6200) -> 596100 | L10: 727100 | M10: 627100
A11: 26.04.01~04.05 | B11: 소노캄 | C11: 룸메이드 | F11: 한애네 | G11: 5 | K11: =M11-(G11*6200) -> 581220 | L11: 712220 | M11: 612220 | P11: AND(ISNUMBER(E5),E5>12) | Q11: 조건
A12: 26.04.01~04.05 | B12: 소노캄 | C12: 룸메이드 | F12: 김미라 | G12: 4 | K12: =M12-(G12*6200) -> 480600 | L12: 585400 | M12: 505400 | P12: SUMPRODUCT(--ISNUMBER(E6:K6), --(E6:K6>12), (E6:K6-12)*(E6:K6<13) + (E6:K6>=13))
A13: 26.04.01~04.05 | B13: 소노캄 | C13: 룸메이드 | F13: 한장미 | G13: 4 | K13: =M13-(G13*6200) -> 489900 | L13: 594700 | M13: 514700
A14: 26.04.01~04.05 | B14: 소노캄 | C14: 룸메이드 | F14: 이노민 | G14: 4 | K14: =M14-(G14*6200) -> 464480 | L14: 569280 | M14: 489280 | P14: *13유닛 미만건에 대해서 차감할건지 확인 - 차감안하기로 함
A15: 26.04.01~04.05 | B15: 소노캄 | C15: 룸메이드 | F15: 박은숙 | G15: 5 | K15: =M15-(G15*6200) -> 591760 | L15: 722760 | M15: 622760
A16: 26.04.01~04.05 | B16: 소노캄 | C16: 룸메이드 | F16: 절멍 | G16: 1 | K16: =M16-(G16*6200) -> 118600 | L16: 144800 | M16: 124800
A17: 26.04.01~04.05 | B17: 소노캄 | C17: 룸메이드 | F17: 투기 | G17: 4 | K17: =M17-(G17*6200) -> 562000 | L17: 686800 | M17: 586800
A18: 26.04.01~04.05 | B18: 소노캄 | C18: 룸메이드 | F18: 본자 | G18: 4 | K18: =M18-(G18*6200) -> 588660 | L18: 713460 | M18: 613460
A19: 26.04.01~04.05 | B19: 소노캄 | C19: 룸메이드 | F19: 이수지 | G19: 1 | K19: =M19-(G19*6200) -> 117980 | L19: 144180 | M19: 124180
A20: 26.04.01~04.05 | B20: 소노캄 | C20: 룸메이드 | F20: 김세인 | G20: 0 | K20: =M20-(G20*6200) -> 98760 | L20: 118760 | M20: 98760
A21: 26.04.01~04.05 | B21: 소노캄 | C21: 룸메이드 | F21: 유빈 | G21: 1 | K21: =M21-(G21*6200) -> 126040 | L21: 152240 | M21: 132240
A22: 26.04.01~04.05 | B22: 소노캄 | C22: 룸메이드 | F22: 아치 | G22: 1 | K22: =M22-(G22*6200) -> 102480 | L22: 128680 | M22: 108680
A23: 26.04.01~04.05 | B23: 소노캄 | C23: 룸메이드 | F23: 미나 | G23: 1 | K23: =M23-(G23*6200) -> 134100 | L23: 160300 | M23: 140300
A24: 26.04.01~04.05 | B24: 소노캄 | C24: 룸메이드 | F24: 우레 | G24: 2 | K24: =M24-(G24*6200) -> 337820 | L24: 410220 | M24: 350220
A25: 26.04.01~04.05 | B25: 소노캄 | C25: 룸메이드 | F25: 강인운 | G25: 4 | K25: =M25-(G25*6200) -> 571920 | L25: 696720 | M25: 596720
A26: 26.04.01~04.05 | B26: 소노캄 | C26: 룸메이드 | F26: 김서라 | G26: 1 | K26: =M26-(G26*6200) -> 125420 | L26: 151620 | M26: 131620
... A125: 26.04.13~04.19 | B125: 소노캄 | C125: 룸메이드 | F125: 나미 | G125: 0 | K125: =M125-(G125*6200) -> 100620 | L125: 120620 | M125: 100620
A126: 26.04.13~04.19 | B126: 소노캄 | C126: 룸메이드 | F126: 유정화 | K126: 0 | L126: 370000 | M126: 0 | N126: 채움으로 지급 진행 / 정산만 휴먼
A127: 26.04.13~04.19 | B127: 소노캄 | C127: 룸메이드 | F127: 정현주 | K127: 0 | L127: 240000 | M127: 0 | N127: 채움으로 지급 진행 / 정산만 휴먼

Sheet 소노캄_런드리
A1: 삼구-소노캄 런드리
N3: 지급액 | O3: =SUM(K3:K9967) -> 3200000 | P3: 청구액 | Q3: =SUM(L3:L9967) -> 3840000
A4: 날짜 | B4: 업체 | C4: 현장 | D4: 업무 | E4: 근무시간 | F4: 이름 | G4: 근무일수 | H4: 주민등록번호 | I4: 은행 | J4: 계좌번호 | K4: 지급액 | L4: 청구액 | M4: 차액
A5: 26.04.01~04.05 | B5: 삼구 | C5: 소노캄 | D5: 런드리 | F5: 보라 | G5: 4 | K5: =G5*100000 -> 400000 | L5: =120000*G5 -> 480000 | M5: =L5-K5 -> 80000 | P5: 소노캄 기물, 런드리
A6: 26.04.01~04.05 | B6: 삼구 | C6: 소노캄 | D6: 런드리 | F6: 너마 | G6: 3 | K6: =G6*100000 -> 300000 | L6: =120000*G6 -> 360000 | M6: =L6-K6 -> 60000 | P6: *청구 11만원
A7: 26.04.01~04.05 | B7: 삼구 | C7: 소노캄 | D7: 런드리 | F7: 아리 | G7: 1 | K7: =G7*100000 -> 100000 | L7: =120000*G7 -> 120000 | M7: =L7-K7 -> 20000 | P7: *지급 10만원
A8: 26.04.06~04.12 | B8: 삼구 | C8: 소노캄 | D8: 런드리 | F8: 보라 | G8: 6 | K8: =G8*100000 -> 600000 | L8: =120000*G8 -> 720000 | M8: =L8-K8 -> 120000
A9: 26.04.06~04.12 | B9: 삼구 | C9: 소노캄 | D9: 런드리 | F9: 너마 | G9: 4 | K9: =G9*100000 -> 400000 | L9: =120000*G9 -> 480000 | M9: =L9-K9 -> 80000
A10: 26.04.13~04.19 | B10: 삼구 | C10: 소노캄 | D10: 런드리 | F10: 보라 | G10: 3 | K10: =G10*100000 -> 300000 | L10: =120000*G10 -> 360000 | M10: =L10-K10 -> 60000
A11: 26.04.13~04.19 | B11: 삼구 | C11: 소노캄 | D11: 런드리 | F11: 한강 | G11: 1 | K11: =G11*100000 -> 100000 | L11: =120000*G11 -> 120000 | M11: =L11-K11 -> 20000
A12: 26.04.13~04.19 | B12: 삼구 | C12: 소노캄 | D12: 런드리 | F12: 조기영 | G12: 4 | K12: =G12*100000 -> 400000 | L12: =120000*G12 -> 480000 | M12: =L12-K12 -> 80000
A13: 26.04.13~04.19 | B13: 삼구 | C13: 소노캄 | D13: 런드리 | F13: 너마 | G13: 6 | K13: =G13*100000 -> 600000 | L13: =120000*G13 -> 720000 | M13: =L13-K13 -> 120000
K14: =G14*100000 -> 0 | L14: =120000*G14 -> 0 | M14: =L14-K14 -> 0
K15: =G15*100000 -> 0 | L15: =120000*G15 -> 0 | M15: =L15-K15 -> 0
K16: =G16*100000 -> 0 | L16: =120000*G16 -> 0 | M16: =L16-K16 -> 0
K17: =G17*100000 -> 0 | L17: =120000*G17 -> 0 | M17: =L17-K17 -> 0
K18: =G18*100000 -> 0 | L18: =120000*G18 -> 0 | M18: =L18-K18 -> 0
K19: =G19*100000 -> 0 | L19: =120000*G19 -> 0 | M19: =L19-K19 -> 0
K20: =G20*100000 -> 0 | L20: =120000*G20 -> 0 | M20: =L20-K20 -> 0
K21: =G21*100000 -> 0 | L21: =120000*G21 -> 0 | M21: =L21-K21 -> 0
K22: =G22*100000 -> 0 | L22: =120000*G22 -> 0 | M22: =L22-K22 -> 0
K23: =G23*100000 -> 0 | L23: =120000*G23 -> 0 | M23: =L23-K23 -> 0
K24: =G24*100000 -> 0 | L24: =120000*G24 -> 0 | M24: =L24-K24 -> 0
K25: =G25*100000 -> 0 | L25: =120000*G25 -> 0 | M25: =L25-K25 -> 0
... K31: =G31*100000 -> 0 | L31: =120000*G31 -> 0 | M31: =L31-K31 -> 0

Sheet 포시
A1: (주)프로에스콤-포시즌스 | M1: 지급액 | N1: =SUM(K3:K9971) -> 11131800 | P1: 청구액 | Q1: =SUM(L3:L9971) -> 12466800
A4: 날짜 | B4: 업체 | C4: 현장 | D4: 업무 | E4: 근무시간 | F4: 이름 | G4: 근무일수 | H4: 주민등록번호 | I4: 은행 | J4: 계좌번호 | K4: 지급액 | L4: 청구액 | M4: 차액 | N4: 입금일
A5: 26.04.01~04.12 | B5: 프로에스콤 | C5: 포시즌스 | D5: 룸메이드 | F5: 다리아 | I5: 우리 | J5: 1002463579165 | K5: 1565500 | L5: 1730500 | M5: =L5-K5 -> 165000 | N5: 4/20 지급
A6: 26.04.01~04.12 | B6: 프로에스콤 | C6: 포시즌스 | D6: 룸메이드 | F6: 버기 | I6: 토스 | J6: 100067464939 | K6: 1704200 | L6: 1884200 | M6: =L6-K6 -> 180000 | N6: 4/20 지급
A7: 26.04.01~04.12 | B7: 프로에스콤 | C7: 포시즌스 | D7: 룸메이드 | F7: 자야 | I7: 토스 | J7: 100202869707 | K7: 991000 | L7: 1096000 | M7: =L7-K7 -> 105000 | N7: 4/20 지급
A8: 26.04.01~04.12 | B8: 프로에스콤 | C8: 포시즌스 | D8: 룸메이드 | F8: 사라 | I8: 토스 | J8: 100125746909 | K8: 1433100 | L8: 1598100 | M8: =L8-K8 -> 165000 | N8: 4/20 지급
A9: 26.04.01~04.12 | B9: 프로에스콤 | C9: 포시즌스 | D9: 룸메이드 | F9: 오양가 | I9: 국민 | J9: 04840204367673 | K9: 1038000 | L9: 1158000 | M9: =L9-K9 -> 120000 | N9: 4/20 지급
A10: 26.04.01~04.12 | B10: 프로에스콤 | C10: 포시즌스 | D10: 룸메이드 | F10: 미나 | I10: 경남 | J10: 8010457913439 | K10: 770000 | L10: 875000 | M10: =L10-K10 -> 105000 | N10: 4/20 지급
A11: 26.04.01~04.12 | B11: 프로에스콤 | C11: 포시즌스 | D11: 배딩조 | F11: 절버 | I11: 우리 | J11: 1002466281395 | K11: 1210000 | L11: 1375000 | M11: =L11-K11 -> 165000 | N11: 4/20 지급
A12: 26.04.01~04.12 | B12: 프로에스콤 | C12: 포시즌스 | D12: 배딩조 | F12: 가나 | I12: 국민 | J12: 22930104344308 | K12: 1100000 | L12: 1250000 | M12: =L12-K12 -> 150000 | N12: 4/20 지급
A13: 26.04.01~04.12 | B13: 프로에스콤 | C13: 포시즌스 | D13: 배딩조 | F13: 주영 | I13: 전북 | J13: 9201032310249 | K13: 990000 | L13: 1125000 | M13: =L13-K13 -> 135000 | N13: 4/20 지급
A14: 26.04.01~04.12 | B14: 프로에스콤 | C14: 포시즌스 | D14: 배딩조 | F14: 도쿠 | I14: 전북 | J14: 9100052891829 | K14: 220000 | L14: 250000 | M14: =L14-K14 -> 30000 | N14: 4/20 지급
A15: 26.04.01~04.12 | B15: 프로에스콤 | C15: 포시즌스 | D15: 배딩조 | F15: 자야2 | I15: 국민 | J15: 22930104344308 | K15: 110000 | L15: 125000 | M15: =L15-K15 -> 15000 | N15: 4/20 지급

Sheet 부산파크
A1: (주)프로에스콤-포시즌스 | N1: 지급액 | O1: =SUM(K1:K9959) -> 350000 | Q1: 청구액 | R1: =SUM(L1:L9959) -> 425000
A2: 날짜 | B2: 업체 | C2: 현장 | D2: 업무 | E2: 근무시간 | F2: 이름 | G2: 근무일수 | H2: 주민등록번호 | I2: 은행 | J2: 계좌번호 | K2: 지급액 | L2: 청구액 | M2: 차액 | N2: 입금일
A3: 26.04.01~04.06 | B3: 프로에스콤 | C3: 파크하얏트 부산 | D3: 룸메이드 | F3: 마야 | I3: 부산 | J3: 1122198905106 | K3: 350000 | L3: 425000 | M3: =L3-K3 -> 75000 | N3: 4/25 지급

Sheet 시그니엘
A1: (주)프로에스콤-시그니엘 | N1: 지급액 | O1: =SUM(K1:K9969) -> 0 | Q1: 청구액 | R1: =SUM(L1:L9969) -> 0
A2: 날짜 | B2: 업체 | C2: 현장 | D2: 업무 | E2: 근무시간 | F2: 이름 | G2: 근무일수 | H2: 주민등록번호 | I2: 은행 | J2: 계좌번호 | K2: 지급액 | L2: 청구액 | M2: 차액 | N2: 입금일
